Workbook

Sheet Sheet1
A1: country_name | B1: account_locator | C1: identifier | D1: email
A2: Taiwan | B2: TQ34613 | C2: TW | D2: =_xlfn.XLOOKUP(Sheet1!C2,PIC!D:D,PIC!E:E,"notfound") -> MinJung.Kim@pmi.com
A3: Armenia | B3: MZ13437 | C3: AM | D3: =_xlfn.XLOOKUP(Sheet1!C3,PIC!D:D,PIC!E:E,"notfound") -> Hamlet.Unusyan@pmi.com
A4: Morocco | B4: GT52354 | C4: MA | D4: =_xlfn.XLOOKUP(Sheet1!C4,PIC!D:D,PIC!E:E,"notfound") -> Mohammed.Abdelfattah@pmi.com
A5: Austria | B5: JP13634 | C5: AT | D5: =_xlfn.XLOOKUP(Sheet1!C5,PIC!D:D,PIC!E:E,"notfound") -> Ankit.Rohatgi@pmi.com
A6: Finland | B6: EA17288 | C6: CNRD | D6: =_xlfn.XLOOKUP(Sheet1!C6,PIC!D:D,PIC!E:E,"notfound") -> Solmaz.Azimi@swma.se
A7: Japan | B7: NB65125 | C7: JP | D7: =_xlfn.XLOOKUP(Sheet1!C7,PIC!D:D,PIC!E:E,"notfound") -> Danny.Chang@pmi.com
A8: Azerbaijan | B8: MU28789 | C8: AZ | D8: =_xlfn.XLOOKUP(Sheet1!C8,PIC!D:D,PIC!E:E,"notfound") -> Hamlet.Unusyan@pmi.com
A9: United States | B9: XDB62269 | C9: US | D9: =_xlfn.XLOOKUP(Sheet1!C9,PIC!D:D,PIC!E:E,"notfound") -> Rafik.Bhura@smpmi.com
A10: Slovenia | B10: TX15762 | C10: CCSL | D10: =_xlfn.XLOOKUP(Sheet1!C10,PIC!D:D,PIC!E:E,"notfound") -> Danijal.Morankic@pmi.com
A11: Republic of Kosovo | B11: NJ29393 | C11: CSEE | D11: nenad.djordjevic@pmi.com
A12: Luxembourg | B12: KC62702 | C12: CBNL | D12: =_xlfn.XLOOKUP(Sheet1!C12,PIC!D:D,PIC!E:E," notfound") -> stefan.verschelden@pmi.com
A13: Croatia | B13: TX15762 | C13: CCSL | D13: =_xlfn.XLOOKUP(Sheet1!C13,PIC!D:D,PIC!E:E," notfound") -> Danijal.Morankic@pmi.com
A14: Mexico | B14: SW91921 | C14: MX | D14: =_xlfn.XLOOKUP(Sheet1!C14,PIC!D:D,PIC!E:E," notfound") -> Daniel.Diaz@pmi.com
A15: Pakistan | B15: ZR99368 | C15: PK | D15: =_xlfn.XLOOKUP(Sheet1!C15,PIC!D:D,PIC!E:E," notfound") -> Zainab.Imran@pmi.com
A16: Jordan | B16: KM45799 | C16: EG | D16: =_xlfn.XLOOKUP(Sheet1!C16,PIC!D:D,PIC!E:E," notfound") -> Mohammed.Abdelfattah@pmi.com
A17: Czech Republic | B17: MN17341 | C17: CZSK | D17: =_xlfn.XLOOKUP(Sheet1!C17,PIC!D:D,PIC!E:E," notfound") -> Adam.Cellar@pmi.com
A18: Belgium | B18: KC62702 | C18: CBNL | D18: =_xlfn.XLOOKUP(Sheet1!C18,PIC!D:D,PIC!E:E," notfound") -> stefan.verschelden@pmi.com
A19: Indonesia | B19: AW40842 | C19: ID | D19: =_xlfn.XLOOKUP(Sheet1!C19,PIC!D:D,PIC!E:E," notfound") -> Ingrid.Wijaya@sampoerna.com
A20: Philippines | B20: KG15403 | C20: PH | D20: =_xlfn.XLOOKUP(Sheet1!C20,PIC!D:D,PIC!E:E," notfound") -> wilhelm.su@pmi.com
A21: Egypt | B21: KM45799 | C21: EG | D21: =_xlfn.XLOOKUP(Sheet1!C21,PIC!D:D,PIC!E:E," notfound") -> Mohammed.Abdelfattah@pmi.com
A22: Malaysia | B22: LS15602 | C22: CMY | D22: WaiKong.Leong@pmi.com
A23: Libya | B23: GT52354 | C23: MA | D23: =_xlfn.XLOOKUP(Sheet1!C23,PIC!D:D,PIC!E:E," notfound") -> Mohammed.Abdelfattah@pmi.com
A24: Ecuador | B24: XP62606 | C24: RAN | D24: =_xlfn.XLOOKUP(Sheet1!C24,PIC!D:D,PIC!E:E," notfound") -> Laura.PerezMonge@pmi.com
A25: Iraq | B25: NV50168 | C25: CME | D25: =_xlfn.XLOOKUP(Sheet1!C25,PIC!D:D,PIC!E:E," notfound") -> Levent.Asici@pmi.com
A26: United Kingdom | B26: AL36445 | C26: UK | D26: =_xlfn.XLOOKUP(Sheet1!C26,PIC!D:D,PIC!E:E," notfound") -> Guilherme.Pedroso@pmi.com
A27: Palestine | B27: KM45799 | C27: EG | D27: =_xlfn.XLOOKUP(Sheet1!C27,PIC!D:D,PIC!E:E," notfound") -> Mohammed.Abdelfattah@pmi.com
A28: Germany | B28: BV97446 | C28: DE | D28: =_xlfn.XLOOKUP(Sheet1!C28,PIC!D:D,PIC!E:E," notfound") -> Michael.Koeniger@pmi.com
A29: South Africa | B29: JC24096 | C29: ZA | D29: Mohammed.Abdelfattah@pmi.com
A30: Tunisia | B30: GT52354 | C30: MA | D30: =_xlfn.XLOOKUP(Sheet1!C30,PIC!D:D,PIC!E:E," notfound") -> Mohammed.Abdelfattah@pmi.com
A31: United Arab Emirates | B31: NV50168 | C31: CME | D31: =_xlfn.XLOOKUP(Sheet1!C31,PIC!D:D,PIC!E:E," notfound") -> Levent.Asici@pmi.com
A32: France | B32: TB87741 | C32: FR | D32: =_xlfn.XLOOKUP(Sheet1!C32,PIC!D:D,PIC!E:E," notfound") -> Xavier.Lachat@pmi.com
A33: Slovakia | B33: MN17341 | C33: CZSK | D33: =_xlfn.XLOOKUP(Sheet1!C33,PIC!D:D,PIC!E:E," notfound") -> Adam.Cellar@pmi.com
A34: Reunion | B34: JC24096 | C34: ZA | D34: Mohammed.Abdelfattah@pmi.com
A35: Portugal | B35: QS39772 | C35: PT | D35: =_xlfn.XLOOKUP(Sheet1!C35,PIC!D:D,PIC!E:E," notfound") -> diogo.algarvio@pmi.com
B36: ZC94311 | C36: KZ | D36: Zhanna.Imanbekova@pmi.com
B37: VP63759 | D37: MinhChuc.Ho@pmi.com

Sheet PIC
A1: Type | B1: Market/Function | C1: Identifier | D1: clean identifier | E1: =IF(F1="","",TRIM(_xlfn.LET( _xlpm.text,F1, _xlpm.startPos,IF(ISNUMBER(SEARCH("DEL =",_xlpm.text)),SEARCH("DEL =",_xlpm.text)+6,IF(ISNUMBER(SEARCH("=",_xlpm.text)),SEARCH("=",_xlpm.text)+2,1)), _xlpm.endPos,IFERROR(SEARCH(";",_xlpm.text,_xlpm.startPos),LEN(_xlpm.text)+1), MID(_xlpm.text,_xlpm.startPos,_xlpm.endPos-_xlpm.startPos) ))) -> Clean Email | F1: Clean Email
A2: Market | B2: ANDEAN (RAN) | C2: RAN | D2: RAN | E2: Laura.PerezMonge@pmi.com | F2: jailer.restrepo@pmi.com
A3: Market | B3: Armenia (AM) | C3: AM | D3: AM | E3: Hamlet.Unusyan@pmi.com | F3: Hamlet.Unusyan@pmi.com
A4: Market | B4: Aspeya | F4: Cristina.Tsiambouris@pmi.com
A5: Market | B5: Australia (AU) & New Zealand (NZ) | C5: AU | D5: AU | E5: Sobitha.Buthgamuwa@pmi.com | F5: Sobitha.Buthgamuwa@pmi.com
A6: Market | B6: Austria (AT) | C6: AT | D6: AT | E6: Ankit.Rohatgi@pmi.com | F6: Ankit.Rohatgi@pmi.com
A7: Market | B7: Azerbaijan (AZ) | C7: AZ | D7: AZ | E7: Hamlet.Unusyan@pmi.com | F7: Hamlet.Unusyan@pmi.com
A8: Market | B8: Baltics Cluster (CBLT) | C8: CBLT | D8: CBLT | E8: Aliaksei.Karneyavets@pmi.com | F8: monika.urbanaviciute@pmi.com
A9: Market | B9: Benelux (CBNL) | C9: CBNL | D9: CBNL | E9: stefan.verschelden@pmi.com | F9: stefan.verschelden@pmi.com
A10: Market | B10: Bulgaria (BG) | C10: BG | D10: BG | E10: Sabina.Rakova@pmi.com | F10: Thanassis.Sagriotis@pmi.com
A11: Market | B11: Brazil (BR) | C11: BR | D11: BR | E11: jonas.cruz@pmi.com | F11: jonas.cruz@pmi.com
A12: Market | B12: Cambodia (KH) | C12: KH | D12: KH | F12: MinhChuc.Ho@pmi.com
A13: Market | B13: Canada (CA) | C13: CA | D13: CA | E13: Preeti.Matkar@rbhinc.ca | F13: joanne.estacion@rbhinc.ca
A14: Market | B14: CARICAM (CCAR) | C14: CCAR | D14: CCAR | F14: Daniel.Diaz@pmi.com
A15: Function | B15: Commercial (COMM) | C15: COMM | D15: COMM | E15: Saputra, Ricky Anders | F15: dorde.rankovic@pmi.com
A16: Function | B16: Consumer (CONS) | C16: CONS | D16: CONS | E16: Salim, Paulus Indra | F16: PaulusIndra.Salim@sampoerna.com
A17: Function | B17: Corporate (CORP) | C17: CORP | D17: CORP | E17: Fernandes, Teresa | F17: Bruna.Carvalho@pmi.com
A18: Market | B18: Croatia & Slovenia (CCSL) | C18: CCSL | D18: CCSL | E18: Danijal.Morankic@pmi.com | F18: Stathis.Fasolis@pmi.com
A19: Market | B19: Cyprus (CY) | C19: CY | D19: CY | E19: Kyriaki.Hadjiossif@pmi.com | F19: stathis.fasolis@pmi.com
A20: Market | B20: Czech (CZ) & Slovakia (SK) | C20: CZ | D20: CZSK | E20: Adam.Cellar@pmi.com | F20: martin.snizek@pmi.com
A21: Function | B21: Duty Free (FDF) | C21: FDF | D21: FDF | E21: Andre.ElKhoury@pmi.com | F21: andre.elkhoury@pmi.com
A22: Capability | B22: EAD (FEA) - Functional EAD node for testing | C22: FEA | D22: FEA | E22: Kamil.Trzepizur@pmi.com | F22: Kamil.Trzepizur@pmi.com
A23: Market | B23: Egypt (EG) | C23: EG | D23: EG | E23: Mohammed.Abdelfattah@pmi.com | F23: Mohammed.Abdelfattah@pmi.com
A24: Admin | B24: Functional Admin Node (FAD) | C24: FAD | D24: FAD | F24: Catarina.Oliveira@pmi.com
A25: Function | B25: Finance (FINC) | C25: FINC | D25: FINC | E25: Fernandes, Teresa | F25: Bruna.Carvalho@pmi.com
A26: Market | B26: France (FR) | C26: FR | D26: FR | E26: Xavier.Lachat@pmi.com | F26: Marwa.Kouriat@pmi.com
A27: Capability | B27: Functional Capability Development (FCD) | C27: FCD | D27: FCD | E27: Kamil.Trzepizur@pmi.com | F27: Kamil.Trzepizur@pmi.com
A28: Capability | B28: Functional Capability Testing (FCT) | C28: FCT | D28: FCT | E28: Kamil.Trzepizur@pmi.com | F28: Kamil.Trzepizur@pmi.com
A29: Market | B29: Georgia (GE) | C29: GE | D29: GE | E29: Hamlet.Unusyan@pmi.com | F29: Hamlet.Unusyan@pmi.com
A30: Market | B30: Germany (DE) | C30: DE | D30: DE | E30: Michael.Koeniger@pmi.com | F30: michael.koeniger@pmi.com
A31: Function | B31: GLPD | E31: Kloc-Kulesza, Ewa | F31: ewa.kloc-kulesza@pmi.com
A32: Market | B32: Greece (GR) | C32: GR | D32: GR | E32: Manos.Mitsis@pmi.com | F32: Vasileios.Botopoulos@pmi.com
A33: Function | B33: IDD (IQAR) | C33: IQAR | D33: IQAR | F33: leonardo.verrastro@pmi.com
A34: Market | B34: India (IN) | C34: IN | D34: IN | F34: CharlesCedric.Tanedo@pmi.com
A35: Market | B35: Indonesia (ID) | C35: ID | D35: ID | E35: Ingrid.Wijaya@sampoerna.com | F35: Ivana.Octavia@sampoerna.com
A36: Market | B36: Israel (IL) | C36: IL | D36: IL | E36: Hamlet.Unusyan@pmi.com | F36: Hamlet.Unusyan@pmi.com
A37: Market | B37: Italy (IT) | C37: IT | D37: IT | E37: Andrea.Guarnieri@pmi.com | F37: Andrea.Guarnieri@pmi.com
A38: Function | B38: InfoSec (INSC) | C38: INSC | D38: INSC | E38: Fernandes, Teresa | F38: Bruna.Carvalho@pmi.com
A39: Function | B39: IT Management (ITMG) | C39: ITMG | D39: ITMG | E39: Fernandes, Teresa | F39: Bruna.Carvalho@pmi.com
A40: Market | B40: Japan | C40: JP | D40: JP | E40: Danny.Chang@pmi.com | F40: Samatha.Arishetty@pmi.com
...
