Workbook

Sheet MasterData
A1: Status | B1: Number | C1: Region | D1: Node Driver | E1: Identifier | F1: Account locator url | G1: Account url | H1: Account Locator | I1: Node Type | J1: domain | K1: Node subtype | L1: Architecture | M1: Ol Markets Finance | N1: Arch Upgrade Activity | O1: Lean IX ID | P1: ACM | Q1: Azure AD APP name | R1: Azure AD app ID
B2: 1 | C2: Indonesia | E2: ID | F2: https://aw40842.eu-west-1.snowflakecomputing.com | G2: https://pmi-pmi_id.snowflakecomputing.com | H2: AW40842 | I2: GEO | J2: market | K2: One Market | L2: old | M2: Indonesia | N2: Upgrade planned Q1 2026 | O2: LX04339 | P2: TRUE | Q2: Snowflake PMI_ID | R2: 60636c8a-6b2a-4e5f-9517-20d22458d6de
B3: 2 | C3: Thailand | E3: TH | F3: https://gb06260.eu-west-1.snowflakecomputing.com | G3: https://pmi-pmi_th.snowflakecomputing.com | H3: GB06260 | I3: GEO | J3: market | K3: One Market | L3: old | M3: Thailand | N3: Upgrade planned Q2 2026 | O3: LX05920 | P3: TRUE | Q3: Snowflake PMI_TH | R3: b5e39e09-a307-4d84-8df5-68c303ca5b3f
B4: 3 | C4: Spain | E4: ES | F4: https://hd52969.eu-west-1.snowflakecomputing.com | G4: https://pmi-pmi_es.snowflakecomputing.com | H4: HD52969 | I4: GEO | J4: market | K4: Cluster Market | L4: old | M4: Spain Mainland, Andorra, Canary Islands | N4: Upgrade planned Q1 2026 | O4: LX06280 | P4: FALSE | Q4: Snowflake PMI_ES | R4: 567f088e-3732-486c-bfd6-b3a97264536d
B5: 4 | C5: Portugal | E5: PT | F5: https://qs39772.eu-west-1.snowflakecomputing.com | G5: https://pmi-pmi_pt.snowflakecomputing.com | H5: QS39772 | I5: GEO | J5: market | K5: One Market | L5: new | M5: Portugal, Azores, Madeira | N5: Upgrade planned Q2 | O5: LX06001 | P5: TRUE | Q5: Snowflake PMI_PT | R5: 54b1f298-2120-4195-bc36-a9d80bd9062f
B6: 5 | C6: Greece | E6: GR | F6: https://kq46976.eu-west-1.snowflakecomputing.com | G6: https://pmi-pmi_gr.snowflakecomputing.com | H6: KQ46976 | I6: GEO | J6: market | K6: One Market | L6: new | M6: Greece | O6: LX06266 | P6: TRUE | Q6: Snowflake PMI_GR | R6: e3a2bd83-bd6b-4659-9db1-79c607514bc4
B7: 6 | C7: Cyprus | E7: CY | F7: https://us15333.eu-west-1.snowflakecomputing.com | G7: https://pmi-pmi_cy.snowflakecomputing.com | H7: US15333 | I7: GEO | J7: market | K7: One Market | L7: new | M7: Cyprus | N7: Upgrade planned Q3 | O7: LX06265 | P7: TRUE | Q7: Snowflake PMI_CY | R7: b4cf3227-000d-4e7e-995e-d40a8a1589e5
B8: 7 | C8: IDD (Function) | E8: IDD | F8: https://ns74854.eu-west-1.snowflakecomputing.com | G8: https://pmi-pmi_idd.snowflakecomputing.com | H8: NS74854 | I8: FUNC | J8: quality | K8: Functional | L8: old | M8: IDD (Function) | O8: LX07466 | P8: FALSE | Q8: Snowflake PMI_IDD | R8: 685393a1-f698-419e-9005-6675e627301c
B9: 8 | C9: Switzerland | E9: CH | F9: https://lq63147.eu-west-1.snowflakecomputing.com | G9: https://pmi-pmi_ch.snowflakecomputing.com | H9: LQ63147 | I9: GEO | J9: market | K9: One Market | L9: old | M9: Switzerland | N9: Upgrade planned Q2 2026 | O9: LX06264 | P9: TRUE | Q9: Snowflake PMI_CH | R9: 3be97f19-9bb1-4ec2-a25e-7c78ea5641a7
B10: 9 | C10: Eastern Europe | E10: EE | F10: https://uj12390.eu-west-1.snowflakecomputing.com | G10: https://pmi-pmi_ee.snowflakecomputing.com | H10: UJ12390 | I10: GEO | J10: market | K10: Cluster Market | L10: new | M10: Eastern Europe | N10: Upgrade planned Q3 | O10: LX05220 | P10: TRUE | Q10: Snowflake PMI_EE | R10: 4594d452-1cac-4e1a-9d79-8e215693df8d
B11: 10 | C11: Egypt | E11: EG | F11: https://km45799.eu-west-1.snowflakecomputing.com | G11: https://pmi-pmi_eg.snowflakecomputing.com | H11: KM45799 | I11: GEO | J11: market | K11: One Market | L11: old | M11: Egypt, Palestine Auth. Area, Jordan, Lebanon | N11: Upgrade planned Q3 2026 | O11: LX06268 | P11: TRUE | Q11: Snowflake PMI_EG | R11: a97a1293-56db-4be2-a0ef-d74ea3e04b8c
B12: 11 | C12: Australia | E12: AU | F12: https://ux99591.eu-west-1.snowflakecomputing.com | G12: https://pmi-pmi_au.snowflakecomputing.com | H12: UX99591 | I12: GEO | J12: market | K12: Cluster Market | L12: new | M12: Australia, New Zealand | O12: LX04642 | P12: TRUE | Q12: Snowflake PMI_AU | R12: 6d146ed0-8e2e-40be-b89a-5b095e03d4e0
B13: 12 | C13: Kazakhstan | E13: KZ | F13: https://zc94311.eu-west-1.snowflakecomputing.com | G13: https://pmi-pmi_kz.snowflakecomputing.com | H13: ZC94311 | I13: GEO | J13: market | K13: One Market | L13: old/new | M13: Kazakhstan | N13: Upgrade started, new markets in new cluster. KZ still here. | O13: LX04785 | P13: N/A | Q13: Snowflake PMI_KZ | R13: 3f112068-0a99-46f5-8ad4-a8f11b309540
B14: 13 | C14: Mexico | E14: MX | F14: https://sw91921.eu-west-1.snowflakecomputing.com | G14: https://pmi-pmi_mx.snowflakecomputing.com | H14: SW91921 | I14: GEO | J14: market | K14: One Market | L14: new | M14: Mexico | N14: Upgrade planned Q4 | O14: LX06272 | P14: TRUE | Q14: Snowflake PMI_MX | R14: dde02f94-87b8-4f4d-9174-265ed2916c96
B15: 14 | C15: Germany | E15: DE | F15: https://bv97446.eu-west-1.snowflakecomputing.com | G15: https://pmi-pmi_de.snowflakecomputing.com | H15: BV97446 | I15: GEO | J15: market | K15: One Market | L15: old | M15: Germany | N15: Upgrade planned Q1 2026 | O15: LX06269 | P15: TRUE | Q15: Snowflake PMI_DE | R15: 427637f0-c66b-4734-83a8-a47cf418bfe2
B16: 15 | C16: United Kingdom | E16: UK | F16: https://al36445.eu-west-1.snowflakecomputing.com | G16: https://pmi-pmi_uk.snowflakecomputing.com | H16: AL36445 | I16: GEO | J16: market | K16: One Market | L16: new | M16: United Kingdom | N16: yes | O16: LX06270 | P16: TRUE | Q16: Snowflake PMI_UK | R16: 37783c60-59ba-484f-9bed-448f63bcaa01
B17: 16 | C17: Czech Republic, Slovak Republic | E17: CZSK | F17: https://mn17341.eu-west-1.snowflakecomputing.com | G17: https://pmi-pmi_czsk.snowflakecomputing.com | H17: MN17341 | I17: GEO | J17: market | K17: Cluster Market | L17: new | M17: Czech Republic, Slovak Republic | N17: Yes | O17: LX05908 | P17: TRUE | Q17: Snowflake PMI_CZSK | R17: 0d0b259f-1de4-4a54-a86d-66bd950dcf98
B18: 17 | C18: France | E18: FR | F18: https://tb87741.eu-west-1.snowflakecomputing.com | G18: https://pmi-pmi_fr.snowflakecomputing.com | H18: TB87741 | I18: GEO | J18: market | K18: One Market | L18: new | M18: France | N18: Upgrade planned Q3 | O18: LX06271 | P18: TRUE | Q18: Snowflake PMI_FR | R18: a507713d-ecc5-416d-94a3-56ada3e62bd4
B19: 18 | C19: India | E19: IN | F19: https://tz27894.eu-west-1.snowflakecomputing.com | G19: https://pmi-pmi_in.snowflakecomputing.com | H19: TZ27894 | I19: GEO | J19: market | K19: One Market | L19: new | M19: India | N19: Upgrade planned Q4 | O19: LX06273 | P19: TRUE | Q19: Snowflake PMI_IN | R19: 69d46527-d22b-40dd-bbcd-d08b626775d8
A20: Inactive | B20: 19 | C20: Cambodia | E20: KH | F20: https://vp63759.eu-west-1.snowflakecomputing.com | G20: https://pmi-pmi_kh.snowflakecomputing.com | H20: VP63759 | I20: GEO | J20: market | K20: One Market | L20: old | M20: FMG Cluster, Cambodia, Bangladesh, Nepal, Maledives | N20: decom | O20: LX06284 | P20: TRUE | Q20: Snowflake PMI_KH | R20: 223ad18b-c632-43ef-a732-4feda868e94c
B21: 20 | C21: Georgia | E21: GE | F21: https://po26476.eu-west-1.snowflakecomputing.com | G21: https://pmi-pmi_ge.snowflakecomputing.com | H21: PO26476 | I21: GEO | J21: market | K21: One Market | L21: new | M21: Georgia | N21: Yes, | O21: LX05216 | P21: TRUE | Q21: Snowflake PMI_GE | R21: 79952c6d-8439-4089-9b37-ffc82dd969e8
B22: 21 | C22: Moldova | E22: MD | F22: https://te25998.eu-west-1.snowflakecomputing.com | G22: https://pmi-pmi_md.snowflakecomputing.com | H22: TE25998 | I22: GEO | J22: market | K22: One Market | L22: new | M22: Moldova | N22: Upgrade planned Q4 | O22: LX05215 | P22: TRUE | Q22: Snowflake PMI_MD | R22: 87ffea58-136b-4b7d-bd75-80ff558038ec
B23: 22 | C23: Armenia | E23: AM | F23: https://mz13437.eu-west-1.snowflakecomputing.com | G23: https://pmi-pmi_am.snowflakecomputing.com | H23: MZ13437 | I23: GEO | J23: market | K23: One Market | L23: new | M23: Armenia | N23: Yes, | O23: LX05217 | P23: TRUE | Q23: Snowflake PMI_AM | R23: d66483cb-628e-446b-90c6-9c8101fce024
B24: 23 | C24: Bulgaria | E24: BG | F24: https://jx90695.eu-west-1.snowflakecomputing.com | G24: https://pmi-pmi_bg.snowflakecomputing.com | H24: JX90695 | I24: GEO | J24: market | K24: One Market | L24: new | M24: Bulgaria | N24: Yes, | O24: LX06285 | P24: TRUE | Q24: Snowflake PMI_BG | R24: 9cfec623-d0c7-4b6e-9073-d5b9c8d9ae03
B25: 24 | C25: Ukraine | E25: UA | F25: https://fu70038.eu-west-1.snowflakecomputing.com | G25: https://pmi-pmi_ua.snowflakecomputing.com | H25: FU70038 | I25: GEO | J25: market | K25: One Market | L25: new | M25: Ukraine | N25: Yes, | O25: LX05219 | P25: TRUE | Q25: Snowflake PMI_UA | R25: 0e818fb9-56e7-4314-ad7d-a849a5200710
A26: Inactive | B26: 25 | C26: Lithuania | E26: LT | F26: https://yq71574.eu-west-1.snowflakecomputing.com | G26: https://pmi-pmi_lt.snowflakecomputing.com | H26: YQ71574 | I26: GEO | J26: market | K26: One Market | L26: old | M26: Lithuania | N26: No upgrade needed. | O26: LX06274 | P26: N/A | Q26: Snowflake PMI_LT | R26: 87848ce8-132a-42c3-ac79-0ff6804f8565
A27: Inactive | B27: 26 | C27: Latvia | E27: LV | F27: https://tj20300.eu-west-1.snowflakecomputing.com | G27: https://pmi-pmi_lv.snowflakecomputing.com | H27: TJ20300 | I27: GEO | J27: market | K27: One Market | L27: old | M27: Latvia | N27: No upgrade needed. | O27: LX06286 | P27: N/A | Q27: Snowflake PMI_LV | R27: c1954344-2c94-4a67-9888-dd28c0a735b6
B28: 27 | C28: Pakistan | E28: PK | F28: https://zr99368.eu-west-1.snowflakecomputing.com | G28: https://pmi-pmi_pk.snowflakecomputing.com | H28: ZR99368 | I28: GEO | J28: market | K28: One Market | L28: old | M28: Pakistan | N28: Upgrade planned Q1 2026 | O28: LX06094 | P28: TRUE | Q28: Snowflake PMI_PK | R28: a64b24ee-e8fa-4412-b1dc-c2cb66016cac
B29: 28 | C29: Philippines | E29: PH | F29: https://kg15403.eu-west-1.snowflakecomputing.com | G29: https://pmi-pmi_ph.snowflakecomputing.com | H29: KG15403 | I29: GEO | J29: market | K29: One Market | L29: old | M29: Philippines | N29: Upgrade planned Q2 2026 | O29: LX06276 | P29: TRUE | Q29: Snowflake PMI_PH | R29: a64b24ee-e8fa-4412-b1dc-c2cb66016cac
A30: Inactive | B30: 29 | C30: Estonia | E30: ET | F30: https://tl15301.eu-west-1.snowflakecomputing.com | G30: https://pmi-pmi_et.snowflakecomputing.com | H30: TL15301 | I30: GEO | J30: market | K30: One Market | L30: old | M30: Estonia | N30: No upgrade needed. | O30: LX06275 | P30: N/A | Q30: Snowflake PMI_ET | R30: 3767fa74-399d-4501-b348-aae36086664d
B31: 30 | C31: Duty Free | E31: FDF | F31: https://pl47603.eu-west-1.snowflakecomputing.com | G31: https://pmi-pmi_fdf.snowflakecomputing.com | H31: PL47603 | I31: GEO | J31: market | K31: Data domain | L31: old | M31: Duty Free/Global Travel retail, PMIDF | N31: Upgrade planned Q3 2026 | O31: LX06287 | P31: TRUE | Q31: Snowflake PMI_FDF | R31: 09887791-ff27-4256-9f48-7409dba50057
B32: 31 | C32: Enterprise Data & Analytics | E32: FEA | F32: https://ng38395.eu-west-1.snowflakecomputing.com | G32: https://pmi-pmi_fea.snowflakecomputing.com | H32: NG38395 | I32: DEVT | J32: DEVT | K32: Development | L32: old | M32: Enterprise Data & Analytics | O32: LX06253 | P32: TRUE | Q32: Snowflake PMI_FEA | R32: e406408f-76f0-47e9-aafa-a62713181ef3
B33: 32 | C33: MEA Regional Account | E33: RME | F33: https://zd75676.eu-west-1.snowflakecomputing.com | G33: https://pmi-pmi_rme.snowflakecomputing.com | H33: ZD75676 | I33: GEO | J33: market | K33: Cluster Market | L33: old | M33: MEA Regional Account | N33: Upgrade planned Q4 2026 | O33: LX06281 | P33: TRUE | Q33: Snowflake PMI_RME | R33: 13e14491-779a-4bad-b283-4de0ddcfafe5
A34: Inactive | B34: 33 | C34: OPS Functional Operations | E34: FOP | F34: https://vq84467.eu-west-1.snowflakecomputing.com | G34: https://pmi-pmi_fop.snowflakecomputing.com | H34: VQ84467 | J34: Operations | K34: Data domain | L34: old | M34: OPS Functional Operations | N34: Decomm | O34: LX06282 | P34: N/A
A35: Inactive | B35: 34 | C35: United States | E35: PMI_US_PHASE_1 | F35: https://sr12280.eu-west-1.snowflakecomputing.com | G35: https://pmi-pmi_us_phase_1.snowflakecomputing.com | H35: SR12280 | J35: market | K35: One Market | L35: new | M35: USA | N35: Node migrated to US region to XDB62269. | O35: LX05918 | P35: N/A
B36: 35 | C36: Andean | E36: RAN | F36: https://xp62606.eu-west-1.snowflakecomputing.com | G36: https://pmi-pmi_ran.snowflakecomputing.com | H36: XP62606 | I36: GEO | J36: market | K36: Cluster Market | L36: new | M36: Andean, Peru, Venezuela, Colombia, Ecuador | N36: Upgrade planned Q4 | O36: LX04764 | P36: TRUE | Q36: Snowflake PMI_RAN | R36: 1442105f-b427-42fe-aa66-a9b86f1740c0
B37: 36 | C37: Italy | E37: IT | F37: https://co95291.eu-west-1.snowflakecomputing.com | G37: https://pmi-pmi_it.snowflakecomputing.com | H37: CO95291 | I37: GEO | J37: market | K37: One Market | L37: new | M37: Italy | N37: Upgrade planned Q2 | O37: LX06289 | P37: TRUE | Q37: Snowflake PMI_IT | R37: 8ff3b7a0-b498-4a5c-a244-c595ad785007
A38: Inactive | B38: 37 | C38: Hungary | E38: HU | F38: https://wn52114.eu-west-1.snowflakecomputing.com | G38: https://pmi-pmi_hu.snowflakecomputing.com | H38: WN52114 | K38: One Market | L38: old | M38: Hungary | N38: Decomm. | P38: N/A
B39: 38 | C39: Poland | E39: PL | F39: https://qs62429.eu-west-1.snowflakecomputing.com | G39: https://pmi-pmi_pl.snowflakecomputing.com | H39: QS62429 | I39: GEO | J39: market | K39: One Market | L39: new | M39: Poland | O39: LX06066 | P39: True | Q39: Snowflake PMI_PL | R39: da8a31c1-87bc-48e3-8267-8ad368da36b8
B40: 39 | C40: Austria | E40: AT | F40: https://jp13634.eu-west-1.snowflakecomputing.com | G40: https://pmi-pmi_at.snowflakecomputing.com | H40: JP13634 | I40: GEO | J40: market | K40: One Market | L40: new | M40: Austria | N40: Upgrade planned Q3 | O40: LX06277 | P40: TRUE | Q40: Snowflake PMI_AT | R40: ed11b418-dd4e-4b5c-8b09-0fe55851d149
...

Sheet ActiveMD
A1: Number | B1: Region Trim | C1: Node Driver | D1: Identifier | E1: Account locator url | F1: Account url | G1: Account Locator | H1: Node Type | I1: domain | J1: Node subtype | K1: Architecture | L1: Ol Markets Finance | M1: Arch Upgrade Activity | N1: Lean IX ID | O1: ACM | P1: Azure AD APP name | Q1: Azure AD app ID
A2: 1 | B2: Indonesia | D2: ID | E2: https://aw40842.eu-west-1.snowflakecomputing.com | F2: https://pmi-pmi_id.snowflakecomputing.com | G2: AW40842 | H2: GEO | I2: market | J2: One Market | K2: old | L2: Indonesia | M2: Upgrade planned Q1 2026 | N2: LX04339 | O2: TRUE | P2: Snowflake PMI_ID | Q2: 60636c8a-6b2a-4e5f-9517-20d22458d6de
A3: 2 | B3: Thailand | D3: TH | E3: https://gb06260.eu-west-1.snowflakecomputing.com | F3: https://pmi-pmi_th.snowflakecomputing.com | G3: GB06260 | H3: GEO | I3: market | J3: One Market | K3: old | L3: Thailand | M3: Upgrade planned Q2 2026 | N3: LX05920 | O3: TRUE | P3: Snowflake PMI_TH | Q3: b5e39e09-a307-4d84-8df5-68c303ca5b3f
A4: 3 | B4: Spain | D4: ES | E4: https://hd52969.eu-west-1.snowflakecomputing.com | F4: https://pmi-pmi_es.snowflakecomputing.com | G4: HD52969 | H4: GEO | I4: market | J4: Cluster Market | K4: old | L4: Spain Mainland, Andorra, Canary Islands | M4: Upgrade planned Q1 2026 | N4: LX06280 | O4: FALSE | P4: Snowflake PMI_ES | Q4: 567f088e-3732-486c-bfd6-b3a97264536d
A5: 4 | B5: Portugal | D5: PT | E5: https://qs39772.eu-west-1.snowflakecomputing.com | F5: https://pmi-pmi_pt.snowflakecomputing.com | G5: QS39772 | H5: GEO | I5: market | J5: One Market | K5: new | L5: Portugal, Azores, Madeira | M5: Upgrade planned Q2 | N5: LX06001 | O5: TRUE | P5: Snowflake PMI_PT | Q5: 54b1f298-2120-4195-bc36-a9d80bd9062f
A6: 5 | B6: Greece | D6: GR | E6: https://kq46976.eu-west-1.snowflakecomputing.com | F6: https://pmi-pmi_gr.snowflakecomputing.com | G6: KQ46976 | H6: GEO | I6: market | J6: One Market | K6: new | L6: Greece | N6: LX06266 | O6: TRUE | P6: Snowflake PMI_GR | Q6: e3a2bd83-bd6b-4659-9db1-79c607514bc4
A7: 6 | B7: Cyprus | D7: CY | E7: https://us15333.eu-west-1.snowflakecomputing.com | F7: https://pmi-pmi_cy.snowflakecomputing.com | G7: US15333 | H7: GEO | I7: market | J7: One Market | K7: new | L7: Cyprus | M7: Upgrade planned Q3 | N7: LX06265 | O7: TRUE | P7: Snowflake PMI_CY | Q7: b4cf3227-000d-4e7e-995e-d40a8a1589e5
A8: 7 | B8: IDD (Function) | D8: IDD | E8: https://ns74854.eu-west-1.snowflakecomputing.com | F8: https://pmi-pmi_idd.snowflakecomputing.com | G8: NS74854 | H8: FUNC | I8: quality | J8: Functional | K8: old | L8: IDD (Function) | N8: LX07466 | O8: FALSE | P8: Snowflake PMI_IDD | Q8: 685393a1-f698-419e-9005-6675e627301c
A9: 8 | B9: Switzerland | D9: CH | E9: https://lq63147.eu-west-1.snowflakecomputing.com | F9: https://pmi-pmi_ch.snowflakecomputing.com | G9: LQ63147 | H9: GEO | I9: market | J9: One Market | K9: old | L9: Switzerland | M9: Upgrade planned Q2 2026 | N9: LX06264 | O9: TRUE | P9: Snowflake PMI_CH | Q9: 3be97f19-9bb1-4ec2-a25e-7c78ea5641a7
A10: 9 | B10: Eastern Europe | D10: EE | E10: https://uj12390.eu-west-1.snowflakecomputing.com | F10: https://pmi-pmi_ee.snowflakecomputing.com | G10: UJ12390 | H10: GEO | I10: market | J10: Cluster Market | K10: new | L10: Eastern Europe | M10: Upgrade planned Q3 | N10: LX05220 | O10: TRUE | P10: Snowflake PMI_EE | Q10: 4594d452-1cac-4e1a-9d79-8e215693df8d
A11: 10 | B11: Egypt | D11: EG | E11: https://km45799.eu-west-1.snowflakecomputing.com | F11: https://pmi-pmi_eg.snowflakecomputing.com | G11: KM45799 | H11: GEO | I11: market | J11: One Market | K11: old | L11: Egypt, Palestine Auth. Area, Jordan, Lebanon | M11: Upgrade planned Q3 2026 | N11: LX06268 | O11: TRUE | P11: Snowflake PMI_EG | Q11: a97a1293-56db-4be2-a0ef-d74ea3e04b8c
A12: 11 | B12: Australia | D12: AU | E12: https://ux99591.eu-west-1.snowflakecomputing.com | F12: https://pmi-pmi_au.snowflakecomputing.com | G12: UX99591 | H12: GEO | I12: market | J12: Cluster Market | K12: new | L12: Australia, New Zealand | N12: LX04642 | O12: TRUE | P12: Snowflake PMI_AU | Q12: 6d146ed0-8e2e-40be-b89a-5b095e03d4e0
A13: 12 | B13: Kazakhstan | D13: KZ | E13: https://zc94311.eu-west-1.snowflakecomputing.com | F13: https://pmi-pmi_kz.snowflakecomputing.com | G13: ZC94311 | H13: GEO | I13: market | J13: One Market | K13: old/new | L13: Kazakhstan | M13: Upgrade started, new markets in new cluster. KZ still here. | N13: LX04785 | O13: N/A | P13: Snowflake PMI_KZ | Q13: 3f112068-0a99-46f5-8ad4-a8f11b309540
A14: 13 | B14: Mexico | D14: MX | E14: https://sw91921.eu-west-1.snowflakecomputing.com | F14: https://pmi-pmi_mx.snowflakecomputing.com | G14: SW91921 | H14: GEO | I14: market | J14: One Market | K14: new | L14: Mexico | M14: Upgrade planned Q4 | N14: LX06272 | O14: TRUE | P14: Snowflake PMI_MX | Q14: dde02f94-87b8-4f4d-9174-265ed2916c96
A15: 14 | B15: Germany | D15: DE | E15: https://bv97446.eu-west-1.snowflakecomputing.com | F15: https://pmi-pmi_de.snowflakecomputing.com | G15: BV97446 | H15: GEO | I15: market | J15: One Market | K15: old | L15: Germany | M15: Upgrade planned Q1 2026 | N15: LX06269 | O15: TRUE | P15: Snowflake PMI_DE | Q15: 427637f0-c66b-4734-83a8-a47cf418bfe2
A16: 15 | B16: United Kingdom | D16: UK | E16: https://al36445.eu-west-1.snowflakecomputing.com | F16: https://pmi-pmi_uk.snowflakecomputing.com | G16: AL36445 | H16: GEO | I16: market | J16: One Market | K16: new | L16: United Kingdom | M16: yes | N16: LX06270 | O16: TRUE | P16: Snowflake PMI_UK | Q16: 37783c60-59ba-484f-9bed-448f63bcaa01
A17: 16 | B17: Czech Republic, Slovak Republic | D17: CZSK | E17: https://mn17341.eu-west-1.snowflakecomputing.com | F17: https://pmi-pmi_czsk.snowflakecomputing.com | G17: MN17341 | H17: GEO | I17: market | J17: Cluster Market | K17: new | L17: Czech Republic, Slovak Republic | M17: Yes | N17: LX05908 | O17: TRUE | P17: Snowflake PMI_CZSK | Q17: 0d0b259f-1de4-4a54-a86d-66bd950dcf98
A18: 17 | B18: France | D18: FR | E18: https://tb87741.eu-west-1.snowflakecomputing.com | F18: https://pmi-pmi_fr.snowflakecomputing.com | G18: TB87741 | H18: GEO | I18: market | J18: One Market | K18: new | L18: France | M18: Upgrade planned Q3 | N18: LX06271 | O18: TRUE | P18: Snowflake PMI_FR | Q18: a507713d-ecc5-416d-94a3-56ada3e62bd4
A19: 18 | B19: India | D19: IN | E19: https://tz27894.eu-west-1.snowflakecomputing.com | F19: https://pmi-pmi_in.snowflakecomputing.com | G19: TZ27894 | H19: GEO | I19: market | J19: One Market | K19: new | L19: India | M19: Upgrade planned Q4 | N19: LX06273 | O19: TRUE | P19: Snowflake PMI_IN | Q19: 69d46527-d22b-40dd-bbcd-d08b626775d8
A20: 20 | B20: Georgia | D20: GE | E20: https://po26476.eu-west-1.snowflakecomputing.com | F20: https://pmi-pmi_ge.snowflakecomputing.com | G20: PO26476 | H20: GEO | I20: market | J20: One Market | K20: new | L20: Georgia | M20: Yes, | N20: LX05216 | O20: TRUE | P20: Snowflake PMI_GE | Q20: 79952c6d-8439-4089-9b37-ffc82dd969e8
A21: 21 | B21: Moldova | D21: MD | E21: https://te25998.eu-west-1.snowflakecomputing.com | F21: https://pmi-pmi_md.snowflakecomputing.com | G21: TE25998 | H21: GEO | I21: market | J21: One Market | K21: new | L21: Moldova | M21: Upgrade planned Q4 | N21: LX05215 | O21: TRUE | P21: Snowflake PMI_MD | Q21: 87ffea58-136b-4b7d-bd75-80ff558038ec
A22: 22 | B22: Armenia | D22: AM | E22: https://mz13437.eu-west-1.snowflakecomputing.com | F22: https://pmi-pmi_am.snowflakecomputing.com | G22: MZ13437 | H22: GEO | I22: market | J22: One Market | K22: new | L22: Armenia | M22: Yes, | N22: LX05217 | O22: TRUE | P22: Snowflake PMI_AM | Q22: d66483cb-628e-446b-90c6-9c8101fce024
A23: 23 | B23: Bulgaria | D23: BG | E23: https://jx90695.eu-west-1.snowflakecomputing.com | F23: https://pmi-pmi_bg.snowflakecomputing.com | G23: JX90695 | H23: GEO | I23: market | J23: One Market | K23: new | L23: Bulgaria | M23: Yes, | N23: LX06285 | O23: TRUE | P23: Snowflake PMI_BG | Q23: 9cfec623-d0c7-4b6e-9073-d5b9c8d9ae03
A24: 24 | B24: Ukraine | D24: UA | E24: https://fu70038.eu-west-1.snowflakecomputing.com | F24: https://pmi-pmi_ua.snowflakecomputing.com | G24: FU70038 | H24: GEO | I24: market | J24: One Market | K24: new | L24: Ukraine | M24: Yes, | N24: LX05219 | O24: TRUE | P24: Snowflake PMI_UA | Q24: 0e818fb9-56e7-4314-ad7d-a849a5200710
A25: 27 | B25: Pakistan | D25: PK | E25: https://zr99368.eu-west-1.snowflakecomputing.com | F25: https://pmi-pmi_pk.snowflakecomputing.com | G25: ZR99368 | H25: GEO | I25: market | J25: One Market | K25: old | L25: Pakistan | M25: Upgrade planned Q1 2026 | N25: LX06094 | O25: TRUE | P25: Snowflake PMI_PK | Q25: a64b24ee-e8fa-4412-b1dc-c2cb66016cac
... A27: 30 | B27: Duty Free | D27: FDF | E27: https://pl47603.eu-west-1.snowflakecomputing.com | F27: https://pmi-pmi_fdf.snowflakecomputing.com | G27: PL47603 | H27: GEO | I27: market | J27: Data domain | K27: old | L27: Duty Free/Global Travel retail, PMIDF | M27: Upgrade planned Q3 2026 | N27: LX06287 | O27: TRUE | P27: Snowflake PMI_FDF | Q27: 09887791-ff27-4256-9f48-7409dba50057
A28: 31 | B28: Enterprise Data & Analytics | D28: FEA | E28: https://ng38395.eu-west-1.snowflakecomputing.com | F28: https://pmi-pmi_fea.snowflakecomputing.com | G28: NG38395 | H28: DEVT | I28: DEVT | J28: Development | K28: old | L28: Enterprise Data & Analytics | N28: LX06253 | O28: TRUE | P28: Snowflake PMI_FEA | Q28: e406408f-76f0-47e9-aafa-a62713181ef3
A29: 32 | B29: MEA Regional Account | D29: RME | E29: https://zd75676.eu-west-1.snowflakecomputing.com | F29: https://pmi-pmi_rme.snowflakecomputing.com | G29: ZD75676 | H29: GEO | I29: market | J29: Cluster Market | K29: old | L29: MEA Regional Account | M29: Upgrade planned Q4 2026 | N29: LX06281 | O29: TRUE | P29: Snowflake PMI_RME | Q29: 13e14491-779a-4bad-b283-4de0ddcfafe5
A30: 35 | B30: Andean | D30: RAN | E30: https://xp62606.eu-west-1.snowflakecomputing.com | F30: https://pmi-pmi_ran.snowflakecomputing.com | G30: XP62606 | H30: GEO | I30: market | J30: Cluster Market | K30: new | L30: Andean, Peru, Venezuela, Colombia, Ecuador | M30: Upgrade planned Q4 | N30: LX04764 | O30: TRUE | P30: Snowflake PMI_RAN | Q30: 1442105f-b427-42fe-aa66-a9b86f1740c0
A31: 36 | B31: Italy | D31: IT | E31: https://co95291.eu-west-1.snowflakecomputing.com | F31: https://pmi-pmi_it.snowflakecomputing.com | G31: CO95291 | H31: GEO | I31: market | J31: One Market | K31: new | L31: Italy | M31: Upgrade planned Q2 | N31: LX06289 | O31: TRUE | P31: Snowflake PMI_IT | Q31: 8ff3b7a0-b498-4a5c-a244-c595ad785007
A32: 38 | B32: Poland | D32: PL | E32: https://qs62429.eu-west-1.snowflakecomputing.com | F32: https://pmi-pmi_pl.snowflakecomputing.com | G32: QS62429 | H32: GEO | I32: market | J32: One Market | K32: new | L32: Poland | N32: LX06066 | O32: True | P32: Snowflake PMI_PL | Q32: da8a31c1-87bc-48e3-8267-8ad368da36b8
A33: 39 | B33: Austria | D33: AT | E33: https://jp13634.eu-west-1.snowflakecomputing.com | F33: https://pmi-pmi_at.snowflakecomputing.com | G33: JP13634 | H33: GEO | I33: market | J33: One Market | K33: new | L33: Austria | M33: Upgrade planned Q3 | N33: LX06277 | O33: TRUE | P33: Snowflake PMI_AT | Q33: ed11b418-dd4e-4b5c-8b09-0fe55851d149
A34: 40 | B34: Morocco | D34: MA | E34: https://gt52354.eu-west-1.snowflakecomputing.com | F34: https://pmi-pmi_ma.snowflakecomputing.com | G34: GT52354 | H34: GEO | I34: market | J34: Cluster Market | K34: old | L34: Morocco, Algeria, Tunisia, Libya | M34: Upgrade planned Q4 2026 | N34: LX06279 | O34: TRUE | P34: Snowflake PMI_MA | Q34: 75d73444-fbe2-4303-b61e-8f921f45e8c3
A35: 41 | B35: Canada | D35: CA | E35: https://in38741.eu-west-1.snowflakecomputing.com | F35: https://pmi-pmi_ca.snowflakecomputing.com | G35: IN38741 | H35: GEO | I35: market | J35: One Market | K35: new | L35: Canada, Canada New | M35: Yes | N35: LX05923 | O35: TRUE | P35: Snowflake PMI_CA | Q35: a0e5214c-5357-42d3-9b51-4eb7de69caff
A36: 42 | B36: Malaysia and Singapore | D36: CMY | E36: https://ls15602.eu-west-1.snowflakecomputing.com | F36: https://pmi-pmi_cmy.snowflakecomputing.com | G36: LS15602 | H36: GEO | I36: market | J36: Cluster Market | K36: new | L36: Malaysia, Singapore | N36: LX05954 | O36: TRUE | P36: Snowflake PMI_MY | Q36: 4680dfec-dd92-49d2-bfdf-3778c0220d86
A37: 45 | B37: Admin Node | D37: FAD | E37: https://lq22027.eu-west-1.snowflakecomputing.com | F37: https://pmi-pmi_fad.snowflakecomputing.com | G37: LQ22027 | H37: ADM | I37: ADM | J37: Admin | K37: new | L37: Admin Node | N37: LX07707 | O37: TRUE | P37: Snowflake PMI_FAD | Q37: d651ed24-7145-4a83-b9cc-af41e960f241
A38: 46 | B38: Supply Chain | D38: SPCH | E38: https://fo55901.eu-west-1.snowflakecomputing.com | F38: https://pmi-pmi_spch.snowflakecomputing.com | G38: FO55901 | H38: FUNC | I38: Operations | J38: Data domain | K38: new | L38: Supply Chain | N38: LX06290 | O38: TRUE | P38: Snowflake PMI_SPCH | Q38: c3ab08a5-6908-47b3-8b3e-8499e4f12ba8
A39: 47 | B39: Functional Capability | D39: FCT | E39: https://id00779.eu-west-1.snowflakecomputing.com | F39: https://pmi-pmi_fct.snowflakecomputing.com | G39: ID00779 | H39: DEVT | I39: DEVT | J39: Development | K39: new | L39: Functional Capability | N39: LX06764 | O39: TRUE | P39: Snowflake PMI_FCT | Q39: ea58b2e7-b1f0-40cd-8e3e-bfa170632386
A40: 48 | B40: Functional Capability Development | D40: FCD | E40: https://mh71026.eu-west-1.snowflakecomputing.com | F40: https://pmi-pmi_fcd.snowflakecomputing.com | G40: MH71026 | H40: DEVT | I40: DEVT | J40: Development | K40: new | L40: Functional Capability Development | N40: LX06763 | O40: TRUE | P40: Snowflake PMI_FCD | Q40: d5b934b8-071f-48b6-bcb7-0bd1ff334b5f
A41: 49 | B41: Finance | D41: FINC | E41: https://ta16206.eu-west-1.snowflakecomputing.com | F41: https://pmi-pmi_finc.snowflakecomputing.com | G41: TA16206 | H41: FUNC | I41: corporate | J41: Data domain | K41: new | L41: Finance | N41: LX06253 | O41: TRUE | P41: Snowflake PMI_FINC | Q41: 7dde77ec-61af-4946-9847-c45ffa0eb992
...

Sheet interactions data sharing
A1: Country Name Ori | B1: Region from DPaaS | C1: Account Locator | E1: mapping account locator to documentation | F1: Matched? | G1: remarks
A2: Taiwan | B2: Taiwan | C2: TQ34613 | D2: =_xlfn.XLOOKUP(TRIM(B2),ActiveMD!B:B,ActiveMD!D:D,"notfound") -> TW | E2: =_xlfn.XLOOKUP(TRIM(C2),ActiveMD!G:G,ActiveMD!D:D,"notfound") -> TW | F2: =IF(D2=E2,D2,"need to be checked") -> TW
A3: Armenia | B3: Armenia | C3: MZ13437 | D3: =_xlfn.XLOOKUP(TRIM(B3),ActiveMD!B:B,ActiveMD!D:D,"notfound") -> AM | E3: =_xlfn.XLOOKUP(TRIM(C3),ActiveMD!G:G,ActiveMD!D:D,"notfound") -> AM | F3: =IF(D3=E3,D3,"need to be checked") -> AM
A4: Morocco | B4: Morocco | C4: GT52354 | D4: =_xlfn.XLOOKUP(TRIM(B4),ActiveMD!B:B,ActiveMD!D:D,"notfound") -> MA | E4: =_xlfn.XLOOKUP(TRIM(C4),ActiveMD!G:G,ActiveMD!D:D,"notfound") -> MA | F4: =IF(D4=E4,D4,"need to be checked") -> MA
A5: Austria | B5: Austria | C5: JP13634 | D5: =_xlfn.XLOOKUP(TRIM(B5),ActiveMD!B:B,ActiveMD!D:D,"notfound") -> AT | E5: =_xlfn.XLOOKUP(TRIM(C5),ActiveMD!G:G,ActiveMD!D:D,"notfound") -> AT | F5: =IF(D5=E5,D5,"need to be checked") -> AT
A6: Dominican Republic | B6: Dominican Republic | C6: XP62606 | D6: =_xlfn.XLOOKUP(TRIM(B6),ActiveMD!B:B,ActiveMD!D:D,"notfound") -> notfound | E6: =_xlfn.XLOOKUP(TRIM(C6),ActiveMD!G:G,ActiveMD!D:D,"notfound") -> RAN | F6: =IF(D6=E6,D6,"need to be checked") -> need to be checked | G6: accloc is andean cluster
A7: Finland | B7: Cluster Nordics | C7: EA17288 | D7: =_xlfn.XLOOKUP(TRIM(B7),ActiveMD!B:B,ActiveMD!D:D,"notfound") -> CNRD | E7: =_xlfn.XLOOKUP(TRIM(C7),ActiveMD!G:G,ActiveMD!D:D,"notfound") -> CNRD | F7: =IF(D7=E7,D7,"need to be checked") -> CNRD | G7: FI for Country Code
A8: Japan | B8: Japan | C8: NB65125 | D8: =_xlfn.XLOOKUP(TRIM(B8),ActiveMD!B:B,ActiveMD!D:D,"notfound") -> JP | E8: =_xlfn.XLOOKUP(TRIM(C8),ActiveMD!G:G,ActiveMD!D:D,"notfound") -> JP | F8: =IF(D8=E8,D8,"need to be checked") -> JP
A9: Azerbaijan | B9: Azerbaijan | C9: MU28789 | D9: =_xlfn.XLOOKUP(TRIM(B9),ActiveMD!B:B,ActiveMD!D:D,"notfound") -> AZ | E9: =_xlfn.XLOOKUP(TRIM(C9),ActiveMD!G:G,ActiveMD!D:D,"notfound") -> AZ | F9: =IF(D9=E9,D9,"need to be checked") -> AZ
A10: United States | B10: United States | C10: XDB62269 | D10: =_xlfn.XLOOKUP(TRIM(B10),ActiveMD!B:B,ActiveMD!D:D,"notfound") -> US | E10: =_xlfn.XLOOKUP(TRIM(C10),ActiveMD!G:G,ActiveMD!D:D,"notfound") -> US | F10: =IF(D10=E10,D10,"need to be checked") -> US
A11: Slovenia | B11: Cluster Croatia Slovenia | C11: TX15762 | D11: =_xlfn.XLOOKUP(TRIM(B11),ActiveMD!B:B,ActiveMD!D:D,"notfound") -> CCSL | E11: =_xlfn.XLOOKUP(TRIM(C11),ActiveMD!G:G,ActiveMD!D:D,"notfound") -> CCSL | F11: =IF(D11=E11,D11,"need to be checked") -> CCSL
A12: Republic of Kosovo | B12: Cluster South East Europe | C12: NJ29393 | D12: =_xlfn.XLOOKUP(TRIM(B12),ActiveMD!B:B,ActiveMD!D:D,"notfound") -> CSEE | E12: =_xlfn.XLOOKUP(TRIM(C12),ActiveMD!G:G,ActiveMD!D:D,"notfound") -> CSEE | F12: =IF(D12=E12,D12,"need to be checked") -> CSEE | G12: RS for country code
A13: Luxembourg | B13: Cluster Benelux | C13: KC62702 | D13: =_xlfn.XLOOKUP(TRIM(B13),ActiveMD!B:B,ActiveMD!D:D,"notfound") -> CBNL | E13: =_xlfn.XLOOKUP(TRIM(C13),ActiveMD!G:G,ActiveMD!D:D,"notfound") -> CBNL | F13: =IF(D13=E13,D13,"need to be checked") -> CBNL
A14: Croatia | B14: Cluster Croatia Slovenia | C14: TX15762 | D14: =_xlfn.XLOOKUP(TRIM(B14),ActiveMD!B:B,ActiveMD!D:D,"notfound") -> CCSL | E14: =_xlfn.XLOOKUP(TRIM(C14),ActiveMD!G:G,ActiveMD!D:D,"notfound") -> CCSL | F14: =IF(D14=E14,D14,"need to be checked") -> CCSL
A15: Mexico | B15: Mexico | C15: SW91921 | D15: =_xlfn.XLOOKUP(TRIM(B15),ActiveMD!B:B,ActiveMD!D:D,"notfound") -> MX | E15: =_xlfn.XLOOKUP(TRIM(C15),ActiveMD!G:G,ActiveMD!D:D,"notfound") -> MX | F15: =IF(D15=E15,D15,"need to be checked") -> MX
A16: Pakistan | B16: Pakistan | C16: ZR99368 | D16: =_xlfn.XLOOKUP(TRIM(B16),ActiveMD!B:B,ActiveMD!D:D,"notfound") -> PK | E16: =_xlfn.XLOOKUP(TRIM(C16),ActiveMD!G:G,ActiveMD!D:D,"notfound") -> PK | F16: =IF(D16=E16,D16,"need to be checked") -> PK
A17: Jordan | B17: Egypt | C17: KM45799 | D17: =_xlfn.XLOOKUP(TRIM(B17),ActiveMD!B:B,ActiveMD!D:D,"notfound") -> EG | E17: =_xlfn.XLOOKUP(TRIM(C17),ActiveMD!G:G,ActiveMD!D:D,"notfound") -> EG | F17: =IF(D17=E17,D17,"need to be checked") -> EG
A18: Czech Republic | B18: Czech Republic, Slovak Republic | C18: MN17341 | D18: =_xlfn.XLOOKUP(TRIM(B18),ActiveMD!B:B,ActiveMD!D:D,"notfound") -> CZSK | E18: =_xlfn.XLOOKUP(TRIM(C18),ActiveMD!G:G,ActiveMD!D:D,"notfound") -> CZSK | F18: =IF(D18=E18,D18,"need to be checked") -> CZSK
A19: Belgium | B19: Cluster Benelux | C19: KC62702 | D19: =_xlfn.XLOOKUP(TRIM(B19),ActiveMD!B:B,ActiveMD!D:D,"notfound") -> CBNL | E19: =_xlfn.XLOOKUP(TRIM(C19),ActiveMD!G:G,ActiveMD!D:D,"notfound") -> CBNL | F19: =IF(D19=E19,D19,"need to be checked") -> CBNL
A20: Indonesia | B20: Indonesia | C20: AW40842 | D20: =_xlfn.XLOOKUP(TRIM(B20),ActiveMD!B:B,ActiveMD!D:D,"notfound") -> ID | E20: =_xlfn.XLOOKUP(TRIM(C20),ActiveMD!G:G,ActiveMD!D:D,"notfound") -> ID | F20: =IF(D20=E20,D20,"need to be checked") -> ID
A21: Philippines | B21: Philippines | C21: KG15403 | D21: =_xlfn.XLOOKUP(TRIM(B21),ActiveMD!B:B,ActiveMD!D:D,"notfound") -> PH | E21: =_xlfn.XLOOKUP(TRIM(C21),ActiveMD!G:G,ActiveMD!D:D,"notfound") -> PH | F21: =IF(D21=E21,D21,"need to be checked") -> PH
A22: Egypt | B22: Egypt | C22: KM45799 | D22: =_xlfn.XLOOKUP(TRIM(B22),ActiveMD!B:B,ActiveMD!D:D,"notfound") -> EG | E22: =_xlfn.XLOOKUP(TRIM(C22),ActiveMD!G:G,ActiveMD!D:D,"notfound") -> EG | F22: =IF(D22=E22,D22,"need to be checked") -> EG
A23: Malaysia | B23: Malaysia and Singapore | C23: LS15602 | D23: =_xlfn.XLOOKUP(TRIM(B23),ActiveMD!B:B,ActiveMD!D:D,"notfound") -> CMY | E23: =_xlfn.XLOOKUP(TRIM(C23),ActiveMD!G:G,ActiveMD!D:D,"notfound") -> CMY | F23: =IF(D23=E23,D23,"need to be checked") -> CMY
A24: Libya | B24: Morocco | C24: GT52354 | D24: =_xlfn.XLOOKUP(TRIM(B24),ActiveMD!B:B,ActiveMD!D:D,"notfound") -> MA | E24: =_xlfn.XLOOKUP(TRIM(C24),ActiveMD!G:G,ActiveMD!D:D,"notfound") -> MA | F24: =IF(D24=E24,D24,"need to be checked") -> MA
A25: Bhutan | B25: Bhutan | C25: VP63759 | D25: =_xlfn.XLOOKUP(TRIM(B25),ActiveMD!B:B,ActiveMD!D:D,"notfound") -> notfound | E25: =_xlfn.XLOOKUP(TRIM(C25),ActiveMD!G:G,ActiveMD!D:D,"notfound") -> notfound | F25: =IF(D25=E25,D25,"need to be checked") -> notfound
A26: Ecuador | B26: Andean | C26: XP62606 | D26: =_xlfn.XLOOKUP(TRIM(B26),ActiveMD!B:B,ActiveMD!D:D,"notfound") -> RAN | E26: =_xlfn.XLOOKUP(TRIM(C26),ActiveMD!G:G,ActiveMD!D:D,"notfound") -> RAN | F26: =IF(D26=E26,D26,"need to be checked") -> RAN | K26: US15333 | L26: this was Cyprus
A27: Iraq | B27: Cluster Middle East | C27: NV50168 | D27: =_xlfn.XLOOKUP(TRIM(B27),ActiveMD!B:B,ActiveMD!D:D,"notfound") -> CME | E27: =_xlfn.XLOOKUP(TRIM(C27),ActiveMD!G:G,ActiveMD!D:D,"notfound") -> CME | F27: =IF(D27=E27,D27,"need to be checked") -> CME | K27: ZC94311 | L27: this was Kazakhstan not Kyrgyzstan
A28: United Kingdom | B28: United Kingdom | C28: AL36445 | D28: =_xlfn.XLOOKUP(TRIM(B28),ActiveMD!B:B,ActiveMD!D:D,"notfound") -> UK | E28: =_xlfn.XLOOKUP(TRIM(C28),ActiveMD!G:G,ActiveMD!D:D,"notfound") -> UK | F28: =IF(D28=E28,D28,"need to be checked") -> UK | K28: VP63759 | L28: deleted
A29: Guatemala | B29: Guatemala | C29: XP62606 | D29: =_xlfn.XLOOKUP(TRIM(B29),ActiveMD!B:B,ActiveMD!D:D,"notfound") -> notfound | E29: =_xlfn.XLOOKUP(TRIM(C29),ActiveMD!G:G,ActiveMD!D:D,"notfound") -> RAN | F29: =IF(D29=E29,D29,"need to be checked") -> need to be checked | G29: accloc is andean cluster
A30: Malta | B30: Malta | C30: US15333 | D30: =_xlfn.XLOOKUP(TRIM(B30),ActiveMD!B:B,ActiveMD!D:D,"notfound") -> notfound | E30: =_xlfn.XLOOKUP(TRIM(C30),ActiveMD!G:G,ActiveMD!D:D,"notfound") -> CY | F30: =IF(D30=E30,D30,"need to be checked") -> need to be checked | G30: accloc is cyprus
A31: Palestine | B31: Egypt | C31: KM45799 | D31: =_xlfn.XLOOKUP(TRIM(B31),ActiveMD!B:B,ActiveMD!D:D,"notfound") -> EG | E31: =_xlfn.XLOOKUP(TRIM(C31),ActiveMD!G:G,ActiveMD!D:D,"notfound") -> EG | F31: =IF(D31=E31,D31,"need to be checked") -> EG
A32: Maldives | B32: Maldives | C32: VP63759 | D32: =_xlfn.XLOOKUP(TRIM(B32),ActiveMD!B:B,ActiveMD!D:D,"notfound") -> notfound | E32: =_xlfn.XLOOKUP(TRIM(C32),ActiveMD!G:G,ActiveMD!D:D,"notfound") -> notfound | F32: =IF(D32=E32,D32,"need to be checked") -> notfound | G32: deleted
A33: Germany | B33: Germany | C33: BV97446 | D33: =_xlfn.XLOOKUP(TRIM(B33),ActiveMD!B:B,ActiveMD!D:D,"notfound") -> DE | E33: =_xlfn.XLOOKUP(TRIM(C33),ActiveMD!G:G,ActiveMD!D:D,"notfound") -> DE | F33: =IF(D33=E33,D33,"need to be checked") -> DE
A34: South Africa | B34: South Africa | C34: JC24096 | D34: =_xlfn.XLOOKUP(TRIM(B34),ActiveMD!B:B,ActiveMD!D:D,"notfound") -> ZA | E34: =_xlfn.XLOOKUP(TRIM(C34),ActiveMD!G:G,ActiveMD!D:D,"notfound") -> ZA | F34: =IF(D34=E34,D34,"need to be checked") -> ZA
A35: Costa Rica | B35: Costa Rica | C35: XP62606 | D35: =_xlfn.XLOOKUP(TRIM(B35),ActiveMD!B:B,ActiveMD!D:D,"notfound") -> notfound | E35: =_xlfn.XLOOKUP(TRIM(C35),ActiveMD!G:G,ActiveMD!D:D,"notfound") -> RAN | F35: =IF(D35=E35,D35,"need to be checked") -> need to be checked | G35: accloc is andean cluster
A36: Tunisia | B36: Morocco | C36: GT52354 | D36: =_xlfn.XLOOKUP(TRIM(B36),ActiveMD!B:B,ActiveMD!D:D,"notfound") -> MA | E36: =_xlfn.XLOOKUP(TRIM(C36),ActiveMD!G:G,ActiveMD!D:D,"notfound") -> MA | F36: =IF(D36=E36,D36,"need to be checked") -> MA
A37: United Arab Emirates | B37: Cluster Middle East | C37: NV50168 | D37: =_xlfn.XLOOKUP(TRIM(B37),ActiveMD!B:B,ActiveMD!D:D,"notfound") -> CME | E37: =_xlfn.XLOOKUP(TRIM(C37),ActiveMD!G:G,ActiveMD!D:D,"notfound") -> CME | F37: =IF(D37=E37,D37,"need to be checked") -> CME
A38: France | B38: France | C38: TB87741 | D38: =_xlfn.XLOOKUP(TRIM(B38),ActiveMD!B:B,ActiveMD!D:D,"notfound") -> FR | E38: =_xlfn.XLOOKUP(TRIM(C38),ActiveMD!G:G,ActiveMD!D:D,"notfound") -> FR | F38: =IF(D38=E38,D38,"need to be checked") -> FR
A39: Slovakia | B39: Czech Republic, Slovak Republic | C39: MN17341 | D39: =_xlfn.XLOOKUP(TRIM(B39),ActiveMD!B:B,ActiveMD!D:D,"notfound") -> CZSK | E39: =_xlfn.XLOOKUP(TRIM(C39),ActiveMD!G:G,ActiveMD!D:D,"notfound") -> CZSK | F39: =IF(D39=E39,D39,"need to be checked") -> CZSK
A40: Kyrgyzstan | B40: Kyrgyzstan | C40: ZC94311 | D40: =_xlfn.XLOOKUP(TRIM(B40),ActiveMD!B:B,ActiveMD!D:D,"notfound") -> notfound | E40: =_xlfn.XLOOKUP(TRIM(C40),ActiveMD!G:G,ActiveMD!D:D,"notfound") -> KZ | F40: =IF(D40=E40,D40,"need to be checked") -> need to be checked | G40: accloc is Kazakhstan
...

Sheet Sheet10
A1: Account Locator | B1: Country | C1: Region | J1: Distinct Account Locator
A2: AL36445 | B2: United Kingdom | C2: United Kingdom | J2: {=_xlfn.UNIQUE(A2:A43)} -> AL36445
A3: AW40842 | B3: Indonesia | C3: Indonesia | J3: AW40842
A4: BV97446 | B4: Germany | C4: Germany | J4: BV97446
A5: EA17288 | B5: Finland | C5: Cluster Nordics | J5: EA17288
A6: GT52354 | B6: Morocco | C6: Morocco | J6: GT52354
A7: GT52354 | B7: Libya | C7: Morocco | J7: JC24096
A8: GT52354 | B8: Tunisia | C8: Morocco | J8: JP13634
A9: JC24096 | B9: South Africa | C9: South Africa | J9: KC62702
A10: JC24096 | B10: Reunion | C10: South Africa | J10: KG15403
A11: JP13634 | B11: Austria | C11: Austria | J11: KM45799
A12: KC62702 | B12: Luxembourg | C12: Cluster Benelux | J12: LS15602
A13: KC62702 | B13: Belgium | C13: Cluster Benelux | J13: MN17341
A14: KG15403 | B14: Philippines | C14: Philippines | J14: MU28789
... A29: XDB62269 | B29: USA | C29: United States | J29: VP63759
A30: SW91921 | B30: Mexico | C30: Mexico
A31: TB87741 | B31: France | C31: France
A32: TQ34613 | B32: Taiwan | C32: Taiwan
A33: TX15762 | B33: Slovenia | C33: Cluster Croatia Slovenia
A34: TX15762 | B34: Croatia | C34: Cluster Croatia Slovenia
A35: US15333 | B35: Malta | C35: Cyprus
A36: XP62606 | B36: Dominican Republic | C36: Andean
A37: XP62606 | B37: Ecuador | C37: Andean
A38: XP62606 | B38: Guatemala | C38: Andean | J38: Account locator used
A39: XP62606 | B39: Costa Rica | C39: Andean | J39: AL36445
A40: ZC94311 | B40: Kyrgyzstan | C40: Kazakhstan | J40: AW40842
A41: ZR99368 | B41: Pakistan | C41: Pakistan | J41: BV97446
A42: VP63759 | B42: Bhutan | C42: Cambodia* | J42: EA17288
A43: VP63759 | B43: Maldives | C43: Cambodia* | J43: GT52354
J44: JC24096
J45: JP13634
J46: KC62702
J47: KG15403
J48: KM45799
J49: LS15602
J50: MN17341
J51: MU28789
J52: MZ13437
J53: NB65125
J54: NJ29393
...

Sheet Sheet6
A1: Country Name Ori | B1: Account Locator | C1: Identifier | D1: mapping account locator to documentation | E1: Matched? | F1: remarks
A2: Taiwan | B2: TQ34613 | C2: TW | D2: TW | E2: TW
A3: Armenia | B3: MZ13437 | C3: AM | D3: AM | E3: AM
A4: Morocco | B4: GT52354 | C4: MA | D4: MA | E4: MA
A5: Austria | B5: JP13634 | C5: AT | D5: AT | E5: AT
A6: Finland | B6: EA17288 | C6: CNRD | D6: CNRD | E6: CNRD
A7: Japan | B7: NB65125 | C7: JP | D7: JP | E7: JP
A8: Azerbaijan | B8: MU28789 | C8: AZ | D8: AZ | E8: AZ
A9: United States | B9: XDB62269 | C9: US | D9: US | E9: US
A10: Slovenia | B10: TX15762 | C10: CCSL | D10: CCSL | E10: CCSL
A11: Republic of Kosovo | B11: NJ29393 | C11: CSEE | D11: CSEE | E11: CSEE
A12: Luxembourg | B12: KC62702 | C12: CBNL | D12: CBNL | E12: CBNL
A13: Croatia | B13: TX15762 | C13: CCSL | D13: CCSL | E13: CCSL
... A35: Portugal | B35: QS39772 | C35: PT | D35: PT | E35: PT
A40: Dominican Republic | B40: XP62606 | C40: notfound | D40: RAN | E40: need to be checked | F40: accloc is andean cluster
A41: Bhutan | B41: VP63759 | C41: notfound | D41: notfound | E41: notfound
A42: Guatemala | B42: XP62606 | C42: notfound | D42: RAN | E42: need to be checked | F42: accloc is andean cluster
A43: Malta | B43: US15333 | C43: notfound | D43: CY | E43: need to be checked | F43: accloc is cyprus
A44: Maldives | B44: VP63759 | C44: notfound | D44: notfound | E44: notfound | F44: deleted
A45: Costa Rica | B45: XP62606 | C45: notfound | D45: RAN | E45: need to be checked | F45: accloc is andean cluster
A46: Kyrgyzstan | B46: ZC94311 | C46: notfound | D46: KZ | E46: need to be checked | F46: accloc is Kazakhstan
A47: Andorra | B47: QS39772 | C47: ES | D47: PT | E47: need to be checked | F47: accloc is Portugal
A48: Vanuatu | D48: notfound | E48: need to be checked | F48: not found
K52: ZC94311
K53: VP63759

Sheet Sheet8
A1: country_name | B1: account_locator | C1: identifier | D1: email | E1: email_single
A2: Taiwan | B2: TQ34613 | C2: TW | D2: =_xlfn.XLOOKUP([1]Sheet1!C2,[1]PIC!D:D,[1]PIC!E:E,"notfound") -> MinJung.Kim@pmi.com | E2: MinJung.Kim@pmi.com
A3: Armenia | B3: MZ13437 | C3: AM | D3: =_xlfn.XLOOKUP([1]Sheet1!C3,[1]PIC!D:D,[1]PIC!E:E,"notfound") -> Hamlet.Unusyan@pmi.com | E3: Hamlet.Unusyan@pmi.com
A4: Morocco | B4: GT52354 | C4: MA | D4: =_xlfn.XLOOKUP([1]Sheet1!C4,[1]PIC!D:D,[1]PIC!E:E,"notfound") -> Mohammed.Abdelfattah@pmi.com | E4: Mohammed.Abdelfattah@pmi.com
A5: Austria | B5: JP13634 | C5: AT | D5: =_xlfn.XLOOKUP([1]Sheet1!C5,[1]PIC!D:D,[1]PIC!E:E,"notfound") -> Ankit.Rohatgi@pmi.com | E5: Ankit.Rohatgi@pmi.com
A6: Finland | B6: EA17288 | C6: CNRD | D6: =_xlfn.XLOOKUP([1]Sheet1!C6,[1]PIC!D:D,[1]PIC!E:E,"notfound") -> Solmaz.Azimi@swma.se | E6: Solmaz.Azimi@swma.se | H6: to FI
A7: Japan | B7: NB65125 | C7: JP | D7: =_xlfn.XLOOKUP([1]Sheet1!C7,[1]PIC!D:D,[1]PIC!E:E,"notfound") -> Danny.Chang@pmi.com | E7: Danny.Chang@pmi.com
A8: Azerbaijan | B8: MU28789 | C8: AZ | D8: =_xlfn.XLOOKUP([1]Sheet1!C8,[1]PIC!D:D,[1]PIC!E:E,"notfound") -> Hamlet.Unusyan@pmi.com | E8: Hamlet.Unusyan@pmi.com
A9: United States | B9: XDB62269 | C9: US | D9: =_xlfn.XLOOKUP([1]Sheet1!C9,[1]PIC!D:D,[1]PIC!E:E,"notfound") -> Rafik.Bhura@smpmi.com | E9: Rafik.Bhura@smpmi.com
A10: Slovenia | B10: TX15762 | C10: CCSL | D10: =_xlfn.XLOOKUP([1]Sheet1!C10,[1]PIC!D:D,[1]PIC!E:E,"notfound") -> Danijal.Morankic@pmi.com | E10: Danijal.Morankic@pmi.com | H10: SI
A11: Republic of Kosovo | B11: NJ29393 | C11: CSEE | D11: nenad.djordjevic@pmi.com | E11: nenad.djordjevic@pmi.com | H11: RS
A12: Luxembourg | B12: KC62702 | C12: CBNL | D12: =_xlfn.XLOOKUP([1]Sheet1!C12,[1]PIC!D:D,[1]PIC!E:E," notfound") -> stefan.verschelden@pmi.com | E12: stefan.verschelden@pmi.com | H12: LU
A13: Croatia | B13: TX15762 | C13: CCSL | D13: =_xlfn.XLOOKUP([1]Sheet1!C13,[1]PIC!D:D,[1]PIC!E:E," notfound") -> Danijal.Morankic@pmi.com | E13: Danijal.Morankic@pmi.com | H13: HR | K13: CZ&SK
A14: Mexico | B14: SW91921 | C14: MX | D14: =_xlfn.XLOOKUP([1]Sheet1!C14,[1]PIC!D:D,[1]PIC!E:E," notfound") -> Daniel.Diaz@pmi.com | E14: Daniel.Diaz@pmi.com
A15: Pakistan | B15: ZR99368 | C15: PK | D15: =_xlfn.XLOOKUP([1]Sheet1!C15,[1]PIC!D:D,[1]PIC!E:E," notfound") -> Zainab.Imran@pmi.com | E15: Zainab.Imran@pmi.com
A16: Jordan | B16: KM45799 | C16: EG | D16: =_xlfn.XLOOKUP([1]Sheet1!C16,[1]PIC!D:D,[1]PIC!E:E," notfound") -> Mohammed.Abdelfattah@pmi.com | E16: Mohammed.Abdelfattah@pmi.com
A17: Czech Republic | B17: MN17341 | C17: CZSK | D17: =_xlfn.XLOOKUP([1]Sheet1!C17,[1]PIC!D:D,[1]PIC!E:E," notfound") -> Adam.Cellar@pmi.com | E17: Adam.Cellar@pmi.com | H17: CZ
A18: Belgium | B18: KC62702 | C18: CBNL | D18: =_xlfn.XLOOKUP([1]Sheet1!C18,[1]PIC!D:D,[1]PIC!E:E," notfound") -> stefan.verschelden@pmi.com | E18: stefan.verschelden@pmi.com | H18: BE
A19: Indonesia | B19: AW40842 | C19: ID | D19: =_xlfn.XLOOKUP([1]Sheet1!C19,[1]PIC!D:D,[1]PIC!E:E," notfound") -> Ingrid.Wijaya@sampoerna.com | E19: Ingrid.Wijaya@sampoerna.com
A20: Philippines | B20: KG15403 | C20: PH | D20: =_xlfn.XLOOKUP([1]Sheet1!C20,[1]PIC!D:D,[1]PIC!E:E," notfound") -> wilhelm.su@pmi.com | E20: wilhelm.su@pmi.com
A21: Egypt | B21: KM45799 | C21: EG | D21: =_xlfn.XLOOKUP([1]Sheet1!C21,[1]PIC!D:D,[1]PIC!E:E," notfound") -> Mohammed.Abdelfattah@pmi.com | E21: Mohammed.Abdelfattah@pmi.com
A22: Malaysia | B22: LS15602 | C22: CMY | D22: WaiKong.Leong@pmi.com | E22: WaiKong.Leong@pmi.com | H22: MY
A23: Libya | B23: GT52354 | C23: MA | D23: =_xlfn.XLOOKUP([1]Sheet1!C23,[1]PIC!D:D,[1]PIC!E:E," notfound") -> Mohammed.Abdelfattah@pmi.com | E23: Mohammed.Abdelfattah@pmi.com
A24: Ecuador | B24: XP62606 | C24: RAN | D24: =_xlfn.XLOOKUP([1]Sheet1!C24,[1]PIC!D:D,[1]PIC!E:E," notfound") -> Laura.PerezMonge@pmi.com | E24: Laura.PerezMonge@pmi.com | H24: EC
A25: Iraq | B25: NV50168 | C25: CME | D25: =_xlfn.XLOOKUP([1]Sheet1!C25,[1]PIC!D:D,[1]PIC!E:E," notfound") -> Levent.Asici@pmi.com | E25: Levent.Asici@pmi.com | H25: IQ
A26: United Kingdom | B26: AL36445 | C26: UK | D26: =_xlfn.XLOOKUP([1]Sheet1!C26,[1]PIC!D:D,[1]PIC!E:E," notfound") -> Guilherme.Pedroso@pmi.com | E26: Guilherme.Pedroso@pmi.com | H26: GB
A27: Palestine | B27: KM45799 | C27: EG | D27: =_xlfn.XLOOKUP([1]Sheet1!C27,[1]PIC!D:D,[1]PIC!E:E," notfound") -> Mohammed.Abdelfattah@pmi.com | E27: Mohammed.Abdelfattah@pmi.com
A28: Germany | B28: BV97446 | C28: DE | D28: =_xlfn.XLOOKUP([1]Sheet1!C28,[1]PIC!D:D,[1]PIC!E:E," notfound") -> Michael.Koeniger@pmi.com | E28: Michael.Koeniger@pmi.com
A29: South Africa | B29: JC24096 | C29: ZA | D29: Mohammed.Abdelfattah@pmi.com | E29: Mohammed.Abdelfattah@pmi.com
A30: Tunisia | B30: GT52354 | C30: MA | D30: =_xlfn.XLOOKUP([1]Sheet1!C30,[1]PIC!D:D,[1]PIC!E:E," notfound") -> Mohammed.Abdelfattah@pmi.com | E30: Mohammed.Abdelfattah@pmi.com
A31: United Arab Emirates | B31: NV50168 | C31: CME | D31: =_xlfn.XLOOKUP([1]Sheet1!C31,[1]PIC!D:D,[1]PIC!E:E," notfound") -> Levent.Asici@pmi.com | E31: Levent.Asici@pmi.com | H31: AE
A32: France | B32: TB87741 | C32: FR | D32: =_xlfn.XLOOKUP([1]Sheet1!C32,[1]PIC!D:D,[1]PIC!E:E," notfound") -> Xavier.Lachat@pmi.com | E32: Xavier.Lachat@pmi.com
A33: Slovakia | B33: MN17341 | C33: CZSK | D33: =_xlfn.XLOOKUP([1]Sheet1!C33,[1]PIC!D:D,[1]PIC!E:E," notfound") -> Adam.Cellar@pmi.com | E33: Adam.Cellar@pmi.com
A34: Reunion | B34: JC24096 | C34: ZA | D34: Mohammed.Abdelfattah@pmi.com | E34: Mohammed.Abdelfattah@pmi.com
A35: Portugal | B35: QS39772 | C35: PT | D35: =_xlfn.XLOOKUP([1]Sheet1!C35,[1]PIC!D:D,[1]PIC!E:E," notfound") -> diogo.algarvio@pmi.com | E35: diogo.algarvio@pmi.com
B36: ZC94311 | C36: KZ | D36: Zhanna.Imanbekova@pmi.com | E36: Zhanna.Imanbekova@pmi.com
B37: VP63759 | D37: MinhChuc.Ho@pmi.com | E37: MinhChuc.Ho@pmi.com

Sheet PIC
A1: Type | B1: Market/Function | C1: Identifier | D1: clean identifier | E1: Clean Email | F1: single email | G1: SPOC/Distribution List | H1: Head of DI&A | I1: DG Lead | J1: single IMDL | K1: IMDL Approvers | L1: Business System Owner | M1: Data Scientist/Analyst Approver | N1: Data Engineer Approver | O1: Technical Lead | P1: Node Owner
A2: Market | B2: ANDEAN (RAN) | C2: =IF(ISNUMBER(FIND("(",B2)),MID(B2,FIND("(",B2)+1,FIND(")",B2)-FIND("(",B2)-1),"") -> RAN | D2: RAN | E2: jailer.restrepo@pmi.com | F2: =IF(G2="","",TRIM(IF(ISNUMBER(FIND(";",G2)),LEFT(G2,FIND(";",G2)-1),G2))) -> jailer.restrepo@pmi.com | G2: jailer.restrepo@pmi.com; alejandro.arboleda@pmi.com; Laura.PerezMonge@pmi.com | H2: Gina.Prieto@pmi.com | I2: Laura.PerezMonge@pmi.com | J2: =IF(K2="","",TRIM(_xlfn.LET( _xlpm.text,K2, _xlpm.startPos,IF(ISNUMBER(SEARCH("DEL =",_xlpm.text)),SEARCH("DEL =",_xlpm.text)+6,IF(ISNUMBER(SEARCH("=",_xlpm.text)),SEARCH("=",_xlpm.text)+2,1)), _xlpm.endPos,IFERROR(SEARCH(";",_xlpm.text,_xlpm.startPos),LEN(_xlpm.text)+1), MID(_xlpm.text,_xlpm.startPos,_xlpm.endPos-_xlpm.startPos) ))) -> Laura.PerezMonge@pmi.com | K2: DEL = Laura.PerezMonge@pmi.com; DE = Laura.PerezMonge@pmi.com; DN= Laura.PerezMonge@pmi.com; DA = Laura.PerezMonge@pmi.com; DS = Laura.PerezMonge@pmi.com; C1 = Laura.PerezMonge@pmi.com | L2: Laura.PerezMonge@pmi.com | M2: tomas.jaramillo@pmi.com | N2: jailer.restrepo@pmi.com | O2: jailer.restrepo@pmi.com | P2: Jessica.Torres@pmi.com
A3: Market | B3: Armenia (AM) | C3: =IF(ISNUMBER(FIND("(",B3)),MID(B3,FIND("(",B3)+1,FIND(")",B3)-FIND("(",B3)-1),"") -> AM | D3: AM | E3: Hamlet.Unusyan@pmi.com | F3: =IF(G3="","",TRIM(IF(ISNUMBER(FIND(";",G3)),LEFT(G3,FIND(";",G3)-1),G3))) -> Hamlet.Unusyan@pmi.com | G3: Hamlet.Unusyan@pmi.com; Tali.Maron-Dotan@pmi.com; | H3: Konstantin.Mityushkin@pmi.com | I3: Konstantin.Mityushkin@pmi.com | J3: =IF(K3="","",TRIM(_xlfn.LET( _xlpm.text,K3, _xlpm.startPos,IF(ISNUMBER(SEARCH("DEL =",_xlpm.text)),SEARCH("DEL =",_xlpm.text)+6,IF(ISNUMBER(SEARCH("=",_xlpm.text)),SEARCH("=",_xlpm.text)+2,1)), _xlpm.endPos,IFERROR(SEARCH(";",_xlpm.text,_xlpm.startPos),LEN(_xlpm.text)+1), MID(_xlpm.text,_xlpm.startPos,_xlpm.endPos-_xlpm.startPos) ))) -> Hamlet.Unusyan@pmi.com | K3: DEL = Hamlet.Unusyan@pmi.com; DE = Hamlet.Unusyan@pmi.com; DN= Hamlet.Unusyan@pmi.com; DA = Hamlet.Unusyan@pmi.com; DS = Hamlet.Unusyan@pmi.com; C1 = Hamlet.Unusyan@pmi.com | L3: Hayk.Haykyan@pmi.com | M3: Hamlet.Unusyan@pmi.com | N3: Hamlet.Unusyan@pmi.com | O3: Hamlet.Unusyan@pmi.com | P3: Tali.Maron-Dotan@pmi.com
A4: Market | B4: Aspeya | C4: =IF(ISNUMBER(FIND("(",B4)),MID(B4,FIND("(",B4)+1,FIND(")",B4)-FIND("(",B4)-1),"") | E4: Cristina.Tsiambouris@pmi.com | F4: =IF(G4="","",TRIM(IF(ISNUMBER(FIND(";",G4)),LEFT(G4,FIND(";",G4)-1),G4))) -> Cristina.Tsiambouris@pmi.com | G4: Cristina.Tsiambouris@pmi.com; | J4: =IF(K4="","",TRIM(_xlfn.LET( _xlpm.text,K4, _xlpm.startPos,IF(ISNUMBER(SEARCH("DEL =",_xlpm.text)),SEARCH("DEL =",_xlpm.text)+6,IF(ISNUMBER(SEARCH("=",_xlpm.text)),SEARCH("=",_xlpm.text)+2,1)), _xlpm.endPos,IFERROR(SEARCH(";",_xlpm.text,_xlpm.startPos),LEN(_xlpm.text)+1), MID(_xlpm.text,_xlpm.startPos,_xlpm.endPos-_xlpm.startPos) ))) | M4: Andrey.Semenov@pmi.com; Scott.Mackenthun@pmi.com | O4: Castillo, Carlos E.
A5: Market | B5: Australia (AU) & New Zealand (NZ) | C5: =IF(ISNUMBER(FIND("(",B5)),MID(B5,FIND("(",B5)+1,FIND(")",B5)-FIND("(",B5)-1),"") -> AU | D5: AU | E5: Sobitha.Buthgamuwa@pmi.com | F5: =IF(G5="","",TRIM(IF(ISNUMBER(FIND(";",G5)),LEFT(G5,FIND(";",G5)-1),G5))) -> Sobitha.Buthgamuwa@pmi.com | G5: Sobitha.Buthgamuwa@pmi.com; Manikam.Nedumaran@contracted.pmi.com; Karen.Molina@pmi.com; YeeMun.Hoi@pmi.com | H5: RobertJoseph.Gereige@pmi.com | J5: =IF(K5="","",TRIM(_xlfn.LET( _xlpm.text,K5, _xlpm.startPos,IF(ISNUMBER(SEARCH("DEL =",_xlpm.text)),SEARCH("DEL =",_xlpm.text)+6,IF(ISNUMBER(SEARCH("=",_xlpm.text)),SEARCH("=",_xlpm.text)+2,1)), _xlpm.endPos,IFERROR(SEARCH(";",_xlpm.text,_xlpm.startPos),LEN(_xlpm.text)+1), MID(_xlpm.text,_xlpm.startPos,_xlpm.endPos-_xlpm.startPos) ))) -> Sobitha.Buthgamuwa@pmi.com | K5: DEL = Sobitha.Buthgamuwa@pmi.com; DE = Sobitha.Buthgamuwa@pmi.com; DN= Sobitha.Buthgamuwa@pmi.com; DA = Sobitha.Buthgamuwa@pmi.com; DS = Sobitha.Buthgamuwa@pmi.com; C1 = Sobitha.Buthgamuwa@pmi.com | L5: YeeMun.Hoi@pmi.com | M5: Sobitha.buthgamuwa@pmi.com | N5: Karen.Molina@pmi.com | O5: Karen.Molina@pmi.com | P5: sobitha.buthgamuwa@pmi.com
A6: Market | B6: Austria (AT) | C6: =IF(ISNUMBER(FIND("(",B6)),MID(B6,FIND("(",B6)+1,FIND(")",B6)-FIND("(",B6)-1),"") -> AT | D6: AT | E6: Ankit.Rohatgi@pmi.com | F6: =IF(G6="","",TRIM(IF(ISNUMBER(FIND(";",G6)),LEFT(G6,FIND(";",G6)-1),G6))) -> Ankit.Rohatgi@pmi.com | G6: Ankit.Rohatgi@pmi.com; eray.sentuerk@pmi.com; frank.goetz@pmi.com; | H6: frank.goetz@pmi.com | I6: Ankit.Rohatgi@pmi.com | J6: =IF(K6="","",TRIM(_xlfn.LET( _xlpm.text,K6, _xlpm.startPos,IF(ISNUMBER(SEARCH("DEL =",_xlpm.text)),SEARCH("DEL =",_xlpm.text)+6,IF(ISNUMBER(SEARCH("=",_xlpm.text)),SEARCH("=",_xlpm.text)+2,1)), _xlpm.endPos,IFERROR(SEARCH(";",_xlpm.text,_xlpm.startPos),LEN(_xlpm.text)+1), MID(_xlpm.text,_xlpm.startPos,_xlpm.endPos-_xlpm.startPos) ))) -> Ankit.Rohatgi@pmi.com | K6: DEL = Ankit.Rohatgi@pmi.com; DE = Ankit.Rohatgi@pmi.com; DN= Ankit.Rohatgi@pmi.com; DA = Ankit.Rohatgi@pmi.com; DS = Ankit.Rohatgi@pmi.com; C1 = Ankit.Rohatgi@pmi.com | L6: Ankit.Rohatgi@pmi.com | M6: frank.goetz@pmi.com | N6: eray.sentuerk@pmi.com | O6: Ankit.Rohatgi@pmi.com; | P6: Jitka.Hajkova@pmi.com
A7: Market | B7: Azerbaijan (AZ) | C7: =IF(ISNUMBER(FIND("(",B7)),MID(B7,FIND("(",B7)+1,FIND(")",B7)-FIND("(",B7)-1),"") -> AZ | D7: AZ | E7: Hamlet.Unusyan@pmi.com | F7: =IF(G7="","",TRIM(IF(ISNUMBER(FIND(";",G7)),LEFT(G7,FIND(";",G7)-1),G7))) -> Hamlet.Unusyan@pmi.com | G7: Hamlet.Unusyan@pmi.com; Tali.Maron-Dotan@pmi.com; | H7: Konstantin.Mityushkin@pmi.com | I7: Konstantin.Mityushkin@pmi.com | J7: =IF(K7="","",TRIM(_xlfn.LET( _xlpm.text,K7, _xlpm.startPos,IF(ISNUMBER(SEARCH("DEL =",_xlpm.text)),SEARCH("DEL =",_xlpm.text)+6,IF(ISNUMBER(SEARCH("=",_xlpm.text)),SEARCH("=",_xlpm.text)+2,1)), _xlpm.endPos,IFERROR(SEARCH(";",_xlpm.text,_xlpm.startPos),LEN(_xlpm.text)+1), MID(_xlpm.text,_xlpm.startPos,_xlpm.endPos-_xlpm.startPos) ))) -> Hamlet.Unusyan@pmi.com | K7: DEL = Hamlet.Unusyan@pmi.com; DE = Hamlet.Unusyan@pmi.com; DN= Hamlet.Unusyan@pmi.com; DA = Hamlet.Unusyan@pmi.com; DS = Hamlet.Unusyan@pmi.com; C1 = Hamlet.Unusyan@pmi.com | L7: Igor.Nikonenko@pmi.com | M7: Hamlet.Unusyan@pmi.com | N7: Hamlet.Unusyan@pmi.com | O7: Hamlet.Unusyan@pmi.com | P7: Tali.Maron-Dotan@pmi.com
A8: Market | B8: Baltics Cluster (CBLT) | C8: =IF(ISNUMBER(FIND("(",B8)),MID(B8,FIND("(",B8)+1,FIND(")",B8)-FIND("(",B8)-1),"") -> CBLT | D8: CBLT | E8: monika.urbanaviciute@pmi.com | F8: =IF(G8="","",TRIM(IF(ISNUMBER(FIND(";",G8)),LEFT(G8,FIND(";",G8)-1),G8))) -> monika.urbanaviciute@pmi.com | G8: monika.urbanaviciute@pmi.com; paula.pratuseviciute@pmi.com; aliaksei.karneyavets@pmi.com; jelena.mirzojeva@pmi.com; | I8: Paula.Pratuseviciute@pmi.com | J8: =IF(K8="","",TRIM(_xlfn.LET( _xlpm.text,K8, _xlpm.startPos,IF(ISNUMBER(SEARCH("DEL =",_xlpm.text)),SEARCH("DEL =",_xlpm.text)+6,IF(ISNUMBER(SEARCH("=",_xlpm.text)),SEARCH("=",_xlpm.text)+2,1)), _xlpm.endPos,IFERROR(SEARCH(";",_xlpm.text,_xlpm.startPos),LEN(_xlpm.text)+1), MID(_xlpm.text,_xlpm.startPos,_xlpm.endPos-_xlpm.startPos) ))) -> Aliaksei.Karneyavets@pmi.com | K8: DEL = Aliaksei.Karneyavets@pmi.com; DE = Paula.Pratuseviciute@pmi.com; DN= Paula.Pratuseviciute@pmi.com; DA = Paula.Pratuseviciute@pmi.com; DS = Paula.Pratuseviciute@pmi.com; C1 = Paula.Pratuseviciute@pmi.com | L8: Paula.Pratuseviciute@pmi.com | M8: Paula.Pratuseviciute@pmi.com | N8: aliaksei.karneyavets@pmi.com | O8: aliaksei.karneyavets@pmi.com | P8: Joanna.Adamczak@pmi.com
A9: Market | B9: Benelux (CBNL) | C9: =IF(ISNUMBER(FIND("(",B9)),MID(B9,FIND("(",B9)+1,FIND(")",B9)-FIND("(",B9)-1),"") -> CBNL | D9: CBNL | E9: stefan.verschelden@pmi.com | F9: =IF(G9="","",TRIM(IF(ISNUMBER(FIND(";",G9)),LEFT(G9,FIND(";",G9)-1),G9))) -> stefan.verschelden@pmi.com | G9: stefan.verschelden@pmi.com; dmitry.dunaev@pmi.com; Thomas.Carrolo@pmi.com; | H9: Alexey.Kayuchenko@pmi.com | J9: =IF(K9="","",TRIM(_xlfn.LET( _xlpm.text,K9, _xlpm.startPos,IF(ISNUMBER(SEARCH("DEL =",_xlpm.text)),SEARCH("DEL =",_xlpm.text)+6,IF(ISNUMBER(SEARCH("=",_xlpm.text)),SEARCH("=",_xlpm.text)+2,1)), _xlpm.endPos,IFERROR(SEARCH(";",_xlpm.text,_xlpm.startPos),LEN(_xlpm.text)+1), MID(_xlpm.text,_xlpm.startPos,_xlpm.endPos-_xlpm.startPos) ))) -> stefan.verschelden@pmi.com | K9: DEL = stefan.verschelden@pmi.com; DE = stefan.verschelden@pmi.com; DN= kamil.sawczak@pmi.com and mladen.vukasinovic@pmi.com; DA = stefan.verschelden@pmi.com; DS = kamil.sawczak@pmi.com and mladen.vukasinovic@pmi.com; C1 = mladen.vukasinovic@pmi.com | L9: stefan.verschelden@pmi.com | M9: dmitry.dunaev@pmi.com | N9: stefan.verschelden@pmi.com | O9: stefan.verschelden@pmi.com | P9: valerie.vanspaendonck@pmi.com
A10: Market | B10: Bulgaria (BG) | C10: =IF(ISNUMBER(FIND("(",B10)),MID(B10,FIND("(",B10)+1,FIND(")",B10)-FIND("(",B10)-1),"") -> BG | D10: BG | E10: Thanassis.Sagriotis@pmi.com | F10: =IF(G10="","",TRIM(IF(ISNUMBER(FIND(";",G10)),LEFT(G10,FIND(";",G10)-1),G10))) -> Thanassis.Sagriotis@pmi.com | G10: Thanassis.Sagriotis@pmi.com; simona.todorova@pmi.com; zlatina.hristova-pencheva@pmi.com; elitsa.deyanova@pmi.com; | H10: Danail.Gardev@pmi.com | J10: =IF(K10="","",TRIM(_xlfn.LET( _xlpm.text,K10, _xlpm.startPos,IF(ISNUMBER(SEARCH("DEL =",_xlpm.text)),SEARCH("DEL =",_xlpm.text)+6,IF(ISNUMBER(SEARCH("=",_xlpm.text)),SEARCH("=",_xlpm.text)+2,1)), _xlpm.endPos,IFERROR(SEARCH(";",_xlpm.text,_xlpm.startPos),LEN(_xlpm.text)+1), MID(_xlpm.text,_xlpm.startPos,_xlpm.endPos-_xlpm.startPos) ))) -> Sabina.Rakova@pmi.com | K10: DEL = Sabina.Rakova@pmi.com; DE = Sabina.Rakova@pmi.com; DN= Sabina.Rakova@pmi.com; DA = Sabina.Rakova@pmi.com; DS = Sabina.Rakova@pmi.com; C1 = Sabina.Rakova@pmi.com | L10: Sabina.Rakova@pmi.com | M10: simona.todorova@pmi.com | N10: Thanassis.Sagriotis@pmi.com; | O10: Thanassis.Sagriotis@pmi.com; ioannis.theodosiou@pmi.com | P10: Stathis.Fasolis@pmi.com
A11: Market | B11: Brazil (BR) | C11: =IF(ISNUMBER(FIND("(",B11)),MID(B11,FIND("(",B11)+1,FIND(")",B11)-FIND("(",B11)-1),"") -> BR | D11: BR | E11: jonas.cruz@pmi.com | F11: =IF(G11="","",TRIM(IF(ISNUMBER(FIND(";",G11)),LEFT(G11,FIND(";",G11)-1),G11))) -> jonas.cruz@pmi.com | G11: jonas.cruz@pmi.com; fernando.varani@pmi.com; Carolinne.Baltazar@pmi.com; camile.fracasso@pmi.com | H11: camile.fracasso@pmi.com | I11: David.Rodrigues@pmi.com | J11: =IF(K11="","",TRIM(_xlfn.LET( _xlpm.text,K11, _xlpm.startPos,IF(ISNUMBER(SEARCH("DEL =",_xlpm.text)),SEARCH("DEL =",_xlpm.text)+6,IF(ISNUMBER(SEARCH("=",_xlpm.text)),SEARCH("=",_xlpm.text)+2,1)), _xlpm.endPos,IFERROR(SEARCH(";",_xlpm.text,_xlpm.startPos),LEN(_xlpm.text)+1), MID(_xlpm.text,_xlpm.startPos,_xlpm.endPos-_xlpm.startPos) ))) -> jonas.cruz@pmi.com | K11: DEL = jonas.cruz@pmi.com; DE = fabio.garcia@pmi.com; DN= jonas.cruz@pmi.com; DA = jonas.cruz@pmi.com; DS = Marcelo.Alarcon@pmi.com; C1 = David.Rodrigues@pmi.com | L11: camile.fracasso@pmi.com | M11: fernando.varani@pmi.com | N11: jonas.cruz@pmi.com | O11: jonas.cruz@pmi.com | P11: Carolinne.Baltazar@pmi.com
A12: Market | B12: Cambodia (KH) | C12: =IF(ISNUMBER(FIND("(",B12)),MID(B12,FIND("(",B12)+1,FIND(")",B12)-FIND("(",B12)-1),"") -> KH | D12: KH | E12: MinhChuc.Ho@pmi.com | F12: =IF(G12="","",TRIM(IF(ISNUMBER(FIND(";",G12)),LEFT(G12,FIND(";",G12)-1),G12))) -> MinhChuc.Ho@pmi.com | G12: MinhChuc.Ho@pmi.com; CharlesCedric.Tanedo@pmi.com; | J12: =IF(K12="","",TRIM(_xlfn.LET( _xlpm.text,K12, _xlpm.startPos,IF(ISNUMBER(SEARCH("DEL =",_xlpm.text)),SEARCH("DEL =",_xlpm.text)+6,IF(ISNUMBER(SEARCH("=",_xlpm.text)),SEARCH("=",_xlpm.text)+2,1)), _xlpm.endPos,IFERROR(SEARCH(";",_xlpm.text,_xlpm.startPos),LEN(_xlpm.text)+1), MID(_xlpm.text,_xlpm.startPos,_xlpm.endPos-_xlpm.startPos) ))) | M12: MinhChuc.Ho@pmi.com | N12: MinhChuc.Ho@pmi.com | O12: MinhChuc.Ho@pmi.com | P12: CharlesCedric.Tanedo@pmi.com
